Workbook

Sheet EST
A1: Name | B1: Monday | C1: Tuesday | D1: Wednesday | E1: Thursday | F1: Friday | G1: Saturday | H1: Sunday | I1: Rest Day | J1: Break 1 | K1: Break 2 | L1: Lunch | M1: Break 3 | N1: Supervisor | O1: EST SHIFT | P1: Column1
A2: Rey Fernandez | B2: 00:00 - 11:00 | C2: OFF | D2: OFF | E2: 00:00 - 11:00 | F2: 00:00 - 11:00 | G2: OFF | H2: 00:00 - 11:00 | I2: =_xlfn.TEXTJOIN(" - ",TRUE, IF(B2="OFF","Mon",""), IF(C2="OFF","Tue",""), IF(D2="OFF","Wed",""), IF(E2="OFF","Thu",""), IF(F2="OFF","Fri",""), IF(G2="OFF","Sat",""), IF(H2="OFF","Sun","")) -> Tue - Wed - Sat | J2: 0.09375 | K2: 0.3125 | L2: 0.1875 | M2: 0.40625 | N2: =VLOOKUP(Table2[[#This Row],[Name]],ROSTER!A:B,2,FALSE) -> Anmecha Valencia | O2: 00:00 - 11:00 | P2: =IF(O2="OFF",0,IF(VALUE(LEFT(O2,2))<12,0,1)) -> 0
A3: Rayniel Ingal | B3: 01:00 - 12:00 | C3: 01:00 - 12:00 | D3: OFF | E3: OFF | F3: OFF | G3: 01:00 - 12:00 | H3: 01:00 - 12:00 | I3: =_xlfn.TEXTJOIN(" - ",TRUE, IF(B3="OFF","Mon",""), IF(C3="OFF","Tue",""), IF(D3="OFF","Wed",""), IF(E3="OFF","Thu",""), IF(F3="OFF","Fri",""), IF(G3="OFF","Sat",""), IF(H3="OFF","Sun","")) -> Wed - Thu - Fri | J3: 0.125 | K3: 0.20833333 | L3: 0.33333333 | M3: 0.45833333 | N3: =VLOOKUP(Table2[[#This Row],[Name]],ROSTER!A:B,2,FALSE) -> Chris Borromeo | O3: 01:00 - 12:00 | P3: =IF(O3="OFF",0,IF(VALUE(LEFT(O3,2))<12,0,1)) -> 0
A4: Aireen Balanon | B4: 02:00 - 13:00 | C4: 02:00 - 13:00 | D4: OFF | E4: OFF | F4: OFF | G4: 02:00 - 13:00 | H4: 02:00 - 13:00 | I4: =_xlfn.TEXTJOIN(" - ",TRUE, IF(B4="OFF","Mon",""), IF(C4="OFF","Tue",""), IF(D4="OFF","Wed",""), IF(E4="OFF","Thu",""), IF(F4="OFF","Fri",""), IF(G4="OFF","Sat",""), IF(H4="OFF","Sun","")) -> Wed - Thu - Fri | J4: 0.16666667 | K4: 0.39583333 | L4: 0.30208333 | M4: 0.48958333 | N4: =VLOOKUP(Table2[[#This Row],[Name]],ROSTER!A:B,2,FALSE) -> Remmo Panaligan | O4: 02:00 - 13:00 | P4: =IF(O4="OFF",0,IF(VALUE(LEFT(O4,2))<12,0,1)) -> 0
A5: Jeffryl Joe Pardillo | B5: 03:00 - 14:00 | C5: 03:00 - 14:00 | D5: 03:00 - 14:00 | E5: OFF | F5: OFF | G5: OFF | H5: 03:00 - 14:00 | I5: =_xlfn.TEXTJOIN(" - ",TRUE, IF(B5="OFF","Mon",""), IF(C5="OFF","Tue",""), IF(D5="OFF","Wed",""), IF(E5="OFF","Thu",""), IF(F5="OFF","Fri",""), IF(G5="OFF","Sat",""), IF(H5="OFF","Sun","")) -> Thu - Fri - Sat | J5: 0.19791667 | K5: 0.41666667 | L5: 0.29166667 | M5: 0.52083333 | N5: =VLOOKUP(Table2[[#This Row],[Name]],ROSTER!A:B,2,FALSE) -> Christopher Rodas | O5: 03:00 - 14:00 | P5: =IF(O5="OFF",0,IF(VALUE(LEFT(O5,2))<12,0,1)) -> 0
A6: Chris Paul Dalut | B6: 04:00 - 15:00 | C6: 04:00 - 15:00 | D6: OFF | E6: 04:00 - 15:00 | F6: 04:00 - 15:00 | G6: OFF | H6: OFF | I6: =_xlfn.TEXTJOIN(" - ",TRUE, IF(B6="OFF","Mon",""), IF(C6="OFF","Tue",""), IF(D6="OFF","Wed",""), IF(E6="OFF","Thu",""), IF(F6="OFF","Fri",""), IF(G6="OFF","Sat",""), IF(H6="OFF","Sun","")) -> Wed - Sat - Sun | J6: 0.23958333 | K6: 0.47916667 | L6: 0.35416667 | M6: 0.58333333 | N6: =VLOOKUP(Table2[[#This Row],[Name]],ROSTER!A:B,2,FALSE) -> Anmecha Valencia | O6: 04:00 - 15:00 | P6: =IF(O6="OFF",0,IF(VALUE(LEFT(O6,2))<12,0,1)) -> 0
A7: Jackyleen Caballero | B7: 06:00 - 17:00 | C7: 06:00 - 17:00 | D7: 06:00 - 17:00 | E7: OFF | F7: OFF | G7: OFF | H7: 06:00 - 17:00 | I7: =_xlfn.TEXTJOIN(" - ",TRUE, IF(B7="OFF","Mon",""), IF(C7="OFF","Tue",""), IF(D7="OFF","Wed",""), IF(E7="OFF","Thu",""), IF(F7="OFF","Fri",""), IF(G7="OFF","Sat",""), IF(H7="OFF","Sun","")) -> Thu - Fri - Sat | J7: 0.34375 | K7: 0.58333333 | L7: 0.45833333 | M7: 0.6875 | N7: =VLOOKUP(Table2[[#This Row],[Name]],ROSTER!A:B,2,FALSE) -> Christopher Rodas | O7: 06:00 - 17:00 | P7: =IF(O7="OFF",0,IF(VALUE(LEFT(O7,2))<12,0,1)) -> 0
A8: Mark Raymond Mangaser Jr | B8: 06:00 - 17:00 | C8: 06:00 - 17:00 | D8: OFF | E8: OFF | F8: OFF | G8: 06:00 - 17:00 | H8: 06:00 - 17:00 | I8: =_xlfn.TEXTJOIN(" - ",TRUE, IF(B8="OFF","Mon",""), IF(C8="OFF","Tue",""), IF(D8="OFF","Wed",""), IF(E8="OFF","Thu",""), IF(F8="OFF","Fri",""), IF(G8="OFF","Sat",""), IF(H8="OFF","Sun","")) -> Wed - Thu - Fri | J8: 0.33333333 | K8: 0.55208333 | L8: 0.42708333 | M8: 0.65625 | N8: =VLOOKUP(Table2[[#This Row],[Name]],ROSTER!A:B,2,FALSE) -> Remmo Panaligan | O8: 06:00 - 17:00 | P8: =IF(O8="OFF",0,IF(VALUE(LEFT(O8,2))<12,0,1)) -> 0
A9: Raquela Nicole Lareta | B9: 06:00 - 17:00 | C9: 06:00 - 17:00 | D9: 06:00 - 17:00 | E9: OFF | F9: OFF | G9: OFF | H9: 06:00 - 17:00 | I9: =_xlfn.TEXTJOIN(" - ",TRUE, IF(B9="OFF","Mon",""), IF(C9="OFF","Tue",""), IF(D9="OFF","Wed",""), IF(E9="OFF","Thu",""), IF(F9="OFF","Fri",""), IF(G9="OFF","Sat",""), IF(H9="OFF","Sun","")) -> Thu - Fri - Sat | J9: 0.33333333 | K9: 0.54166667 | L9: 0.41666667 | M9: 0.65625 | N9: =VLOOKUP(Table2[[#This Row],[Name]],ROSTER!A:B,2,FALSE) -> Christopher Rodas | O9: 06:00 - 17:00 | P9: =IF(O9="OFF",0,IF(VALUE(LEFT(O9,2))<12,0,1)) -> 0
A10: Giselle Florendo | B10: 07:00 - 18:00 | C10: 07:00 - 18:00 | D10: 07:00 - 18:00 | E10: 07:00 - 18:00 | F10: OFF | G10: OFF | H10: OFF | I10: =_xlfn.TEXTJOIN(" - ",TRUE, IF(B10="OFF","Mon",""), IF(C10="OFF","Tue",""), IF(D10="OFF","Wed",""), IF(E10="OFF","Thu",""), IF(F10="OFF","Fri",""), IF(G10="OFF","Sat",""), IF(H10="OFF","Sun","")) -> Fri - Sat - Sun | J10: 0.38541667 | K10: 0.60416667 | L10: 0.47916667 | M10: 0.69791667 | N10: =VLOOKUP(Table2[[#This Row],[Name]],ROSTER!A:B,2,FALSE) -> Remmo Panaligan | O10: 07:00 - 18:00 | P10: =IF(O10="OFF",0,IF(VALUE(LEFT(O10,2))<12,0,1)) -> 0
A11: Joemie Ann Benedicto | B11: 07:00 - 18:00 | C11: 07:00 - 18:00 | D11: 07:00 - 18:00 | E11: 07:00 - 18:00 | F11: OFF | G11: OFF | H11: OFF | I11: =_xlfn.TEXTJOIN(" - ",TRUE, IF(B11="OFF","Mon",""), IF(C11="OFF","Tue",""), IF(D11="OFF","Wed",""), IF(E11="OFF","Thu",""), IF(F11="OFF","Fri",""), IF(G11="OFF","Sat",""), IF(H11="OFF","Sun","")) -> Fri - Sat - Sun | J11: 0.375 | K11: 0.59375 | L11: 0.46875 | M11: 0.6875 | N11: =VLOOKUP(Table2[[#This Row],[Name]],ROSTER!A:B,2,FALSE) -> Remmo Panaligan | O11: 07:00 - 18:00 | P11: =IF(O11="OFF",0,IF(VALUE(LEFT(O11,2))<12,0,1)) -> 0
A12: Roy Sagales | B12: 08:00 - 19:00 | C12: 08:00 - 19:00 | D12: OFF | E12: OFF | F12: OFF | G12: 08:00 - 19:00 | H12: 08:00 - 19:00 | I12: =_xlfn.TEXTJOIN(" - ",TRUE, IF(B12="OFF","Mon",""), IF(C12="OFF","Tue",""), IF(D12="OFF","Wed",""), IF(E12="OFF","Thu",""), IF(F12="OFF","Fri",""), IF(G12="OFF","Sat",""), IF(H12="OFF","Sun","")) -> Wed - Thu - Fri | J12: 0.40625 | K12: 0.61458333 | L12: 0.48958333 | M12: 0.71875 | N12: =VLOOKUP(Table2[[#This Row],[Name]],ROSTER!A:B,2,FALSE) -> Michael Dominguez | O12: 08:00 - 19:00 | P12: =IF(O12="OFF",0,IF(VALUE(LEFT(O12,2))<12,0,1)) -> 0
A13: Shiela Mae Laroa | B13: 08:00 - 19:00 | C13: 08:00 - 19:00 | D13: 08:00 - 19:00 | E13: 08:00 - 19:00 | F13: OFF | G13: OFF | H13: OFF | I13: =_xlfn.TEXTJOIN(" - ",TRUE, IF(B13="OFF","Mon",""), IF(C13="OFF","Tue",""), IF(D13="OFF","Wed",""), IF(E13="OFF","Thu",""), IF(F13="OFF","Fri",""), IF(G13="OFF","Sat",""), IF(H13="OFF","Sun","")) -> Fri - Sat - Sun | J13: 0.41666667 | K13: 0.52083333 | L13: 0.625 | M13: 0.71875 | N13: =VLOOKUP(Table2[[#This Row],[Name]],ROSTER!A:B,2,FALSE) -> Manilyn Abellar | O13: 08:00 - 19:00 | P13: =IF(O13="OFF",0,IF(VALUE(LEFT(O13,2))<12,0,1)) -> 0
... A67: Mary Angelie Fajardo | B67: OFF | C67: OFF | D67: OFF | E67: 21:00 - 08:00 | F67: 21:00 - 08:00 | G67: 21:00 - 08:00 | H67: 21:00 - 08:00 | I67: =_xlfn.TEXTJOIN(" - ",TRUE, IF(B67="OFF","Mon",""), IF(C67="OFF","Tue",""), IF(D67="OFF","Wed",""), IF(E67="OFF","Thu",""), IF(F67="OFF","Fri",""), IF(G67="OFF","Sat",""), IF(H67="OFF","Sun","")) -> Mon - Tue - Wed | J67: 0.95833333 | K67: 0.0625 | L67: 0.14583333 | M67: 0.29166667 | N67: =VLOOKUP(Table2[[#This Row],[Name]],ROSTER!A:B,2,FALSE) -> Christopher Rodas | O67: 21:00 - 08:00 | P67: =IF(O67="OFF",0,IF(VALUE(LEFT(O67,2))<12,0,1)) -> 1

Sheet PH
A1: Name | B1: Monday | C1: Tuesday | D1: Wednesday | E1: Thursday | F1: Friday | G1: Saturday | H1: Sunday | I1: Rest Day | J1: Break 1 | K1: Break 2 | L1: Lunch | M1: Break 3 | N1: Supervisor | O1: PH SHIFT | P1: OFFSET
A2: =Table2[[#This Row],[Name]] -> Rey Fernandez | B2: =IFERROR(_xlfn.LET(_xlpm.s,SUBSTITUTE(IF(Table2[[#This Row],[Column1]]=1,Table2[[#This Row],[Sunday]],Table2[[#This Row],[Monday]])," ",""),IF(_xlpm.s="OFF","OFF",TEXT(MOD(TIMEVALUE(_xlfn.TEXTBEFORE(_xlpm.s,"-"))+0.5,1),"hh:mm")&" - "&TEXT(MOD(TIMEVALUE(_xlfn.TEXTAFTER(_xlpm.s,"-"))+0.5,1),"hh:mm"))),IF(Table2[[#This Row],[Column1]]=1,Table2[[#This Row],[Sunday]],Table2[[#This Row],[Monday]])) -> 12:00 - 23:00 | C2: =IFERROR(_xlfn.LET(_xlpm.s,SUBSTITUTE(IF(Table2[[#This Row],[Column1]]=1,Table2[[#This Row],[Monday]],Table2[[#This Row],[Tuesday]])," ",""),IF(_xlpm.s="OFF","OFF",TEXT(MOD(TIMEVALUE(_xlfn.TEXTBEFORE(_xlpm.s,"-"))+0.5,1),"hh:mm")&" - "&TEXT(MOD(TIMEVALUE(_xlfn.TEXTAFTER(_xlpm.s,"-"))+0.5,1),"hh:mm"))),IF(Table2[[#This Row],[Column1]]=1,Table2[[#This Row],[Monday]],Table2[[#This Row],[Tuesday]])) -> OFF | D2: =IFERROR(_xlfn.LET(_xlpm.s,SUBSTITUTE(IF(Table2[[#This Row],[Column1]]=1,Table2[[#This Row],[Tuesday]],Table2[[#This Row],[Wednesday]])," ",""),IF(_xlpm.s="OFF","OFF",TEXT(MOD(TIMEVALUE(_xlfn.TEXTBEFORE(_xlpm.s,"-"))+0.5,1),"hh:mm")&" - "&TEXT(MOD(TIMEVALUE(_xlfn.TEXTAFTER(_xlpm.s,"-"))+0.5,1),"hh:mm"))),IF(Table2[[#This Row],[Column1]]=1,Table2[[#This Row],[Tuesday]],Table2[[#This Row],[Wednesday]])) -> OFF | E2: =IFERROR(_xlfn.LET(_xlpm.s,SUBSTITUTE(IF(Table2[[#This Row],[Column1]]=1,Table2[[#This Row],[Wednesday]],Table2[[#This Row],[Thursday]])," ",""),IF(_xlpm.s="OFF","OFF",TEXT(MOD(TIMEVALUE(_xlfn.TEXTBEFORE(_xlpm.s,"-"))+0.5,1),"hh:mm")&" - "&TEXT(MOD(TIMEVALUE(_xlfn.TEXTAFTER(_xlpm.s,"-"))+0.5,1),"hh:mm"))),IF(Table2[[#This Row],[Column1]]=1,Table2[[#This Row],[Wednesday]],Table2[[#This Row],[Thursday]])) -> 12:00 - 23:00 | F2: =IFERROR(_xlfn.LET(_xlpm.s,SUBSTITUTE(IF(Table2[[#This Row],[Column1]]=1,Table2[[#This Row],[Thursday]],Table2[[#This Row],[Friday]])," ",""),IF(_xlpm.s="OFF","OFF",TEXT(MOD(TIMEVALUE(_xlfn.TEXTBEFORE(_xlpm.s,"-"))+0.5,1),"hh:mm")&" - "&TEXT(MOD(TIMEVALUE(_xlfn.TEXTAFTER(_xlpm.s,"-"))+0.5,1),"hh:mm"))),IF(Table2[[#This Row],[Column1]]=1,Table2[[#This Row],[Thursday]],Table2[[#This Row],[Friday]])) -> 12:00 - 23:00 | G2: =IFERROR(_xlfn.LET(_xlpm.s,SUBSTITUTE(IF(Table2[[#This Row],[Column1]]=1,Table2[[#This Row],[Friday]],Table2[[#This Row],[Saturday]])," ",""),IF(_xlpm.s="OFF","OFF",TEXT(MOD(TIMEVALUE(_xlfn.TEXTBEFORE(_xlpm.s,"-"))+0.5,1),"hh:mm")&" - "&TEXT(MOD(TIMEVALUE(_xlfn.TEXTAFTER(_xlpm.s,"-"))+0.5,1),"hh:mm"))),IF(Table2[[#This Row],[Column1]]=1,Table2[[#This Row],[Friday]],Table2[[#This Row],[Saturday]])) -> OFF | H2: =IFERROR(_xlfn.LET(_xlpm.s,SUBSTITUTE(IF(Table2[[#This Row],[Column1]]=1,Table2[[#This Row],[Saturday]],Table2[[#This Row],[Sunday]])," ",""),IF(_xlpm.s="OFF","OFF",TEXT(MOD(TIMEVALUE(_xlfn.TEXTBEFORE(_xlpm.s,"-"))+0.5,1),"hh:mm")&" - "&TEXT(MOD(TIMEVALUE(_xlfn.TEXTAFTER(_xlpm.s,"-"))+0.5,1),"hh:mm"))),IF(Table2[[#This Row],[Column1]]=1,Table2[[#This Row],[Saturday]],Table2[[#This Row],[Sunday]])) -> 12:00 - 23:00 | I2: =_xlfn.TEXTJOIN(" - ",TRUE, IF(B2="OFF","Mon",""), IF(C2="OFF","Tue",""), IF(D2="OFF","Wed",""), IF(E2="OFF","Thu",""), IF(F2="OFF","Fri",""), IF(G2="OFF","Sat",""), IF(H2="OFF","Sun","")) -> Tue - Wed - Sat | J2: =MOD(Table2[[#This Row],[Break 1]]+TIME(12,0,0),1) -> 0.59375 | K2: =MOD(Table2[[#This Row],[Break 2]]+TIME(12,0,0),1) -> 0.8125 | L2: =MOD(Table2[[#This Row],[Lunch]]+TIME(12,0,0),1) -> 0.6875 | M2: =MOD(Table2[[#This Row],[Break 3]]+TIME(12,0,0),1) -> 0.90625 | N2: =Table2[[#This Row],[Supervisor]] -> Anmecha Valencia | O2: =TEXT(TIMEVALUE(LEFT(Table2[[#This Row],[EST SHIFT]],5))+12/24,"hh:mm") & " - " & TEXT(TIMEVALUE(RIGHT(Table2[[#This Row],[EST SHIFT]],5))+12/24,"hh:mm") -> 12:00 - 23:00 | P2: =IF(TIMEVALUE(LEFT(O2,FIND("-",O2)-1))>=12/24,0,1) -> 0
A3: =Table2[[#This Row],[Name]] -> Rayniel Ingal | B3: =IFERROR(_xlfn.LET(_xlpm.s,SUBSTITUTE(IF(Table2[[#This Row],[Column1]]=1,Table2[[#This Row],[Sunday]],Table2[[#This Row],[Monday]])," ",""),IF(_xlpm.s="OFF","OFF",TEXT(MOD(TIMEVALUE(_xlfn.TEXTBEFORE(_xlpm.s,"-"))+0.5,1),"hh:mm")&" - "&TEXT(MOD(TIMEVALUE(_xlfn.TEXTAFTER(_xlpm.s,"-"))+0.5,1),"hh:mm"))),IF(Table2[[#This Row],[Column1]]=1,Table2[[#This Row],[Sunday]],Table2[[#This Row],[Monday]])) -> 13:00 - 00:00 | C3: =IFERROR(_xlfn.LET(_xlpm.s,SUBSTITUTE(IF(Table2[[#This Row],[Column1]]=1,Table2[[#This Row],[Monday]],Table2[[#This Row],[Tuesday]])," ",""),IF(_xlpm.s="OFF","OFF",TEXT(MOD(TIMEVALUE(_xlfn.TEXTBEFORE(_xlpm.s,"-"))+0.5,1),"hh:mm")&" - "&TEXT(MOD(TIMEVALUE(_xlfn.TEXTAFTER(_xlpm.s,"-"))+0.5,1),"hh:mm"))),IF(Table2[[#This Row],[Column1]]=1,Table2[[#This Row],[Monday]],Table2[[#This Row],[Tuesday]])) -> 13:00 - 00:00 | D3: =IFERROR(_xlfn.LET(_xlpm.s,SUBSTITUTE(IF(Table2[[#This Row],[Column1]]=1,Table2[[#This Row],[Tuesday]],Table2[[#This Row],[Wednesday]])," ",""),IF(_xlpm.s="OFF","OFF",TEXT(MOD(TIMEVALUE(_xlfn.TEXTBEFORE(_xlpm.s,"-"))+0.5,1),"hh:mm")&" - "&TEXT(MOD(TIMEVALUE(_xlfn.TEXTAFTER(_xlpm.s,"-"))+0.5,1),"hh:mm"))),IF(Table2[[#This Row],[Column1]]=1,Table2[[#This Row],[Tuesday]],Table2[[#This Row],[Wednesday]])) -> OFF | E3: =IFERROR(_xlfn.LET(_xlpm.s,SUBSTITUTE(IF(Table2[[#This Row],[Column1]]=1,Table2[[#This Row],[Wednesday]],Table2[[#This Row],[Thursday]])," ",""),IF(_xlpm.s="OFF","OFF",TEXT(MOD(TIMEVALUE(_xlfn.TEXTBEFORE(_xlpm.s,"-"))+0.5,1),"hh:mm")&" - "&TEXT(MOD(TIMEVALUE(_xlfn.TEXTAFTER(_xlpm.s,"-"))+0.5,1),"hh:mm"))),IF(Table2[[#This Row],[Column1]]=1,Table2[[#This Row],[Wednesday]],Table2[[#This Row],[Thursday]])) -> OFF | F3: =IFERROR(_xlfn.LET(_xlpm.s,SUBSTITUTE(IF(Table2[[#This Row],[Column1]]=1,Table2[[#This Row],[Thursday]],Table2[[#This Row],[Friday]])," ",""),IF(_xlpm.s="OFF","OFF",TEXT(MOD(TIMEVALUE(_xlfn.TEXTBEFORE(_xlpm.s,"-"))+0.5,1),"hh:mm")&" - "&TEXT(MOD(TIMEVALUE(_xlfn.TEXTAFTER(_xlpm.s,"-"))+0.5,1),"hh:mm"))),IF(Table2[[#This Row],[Column1]]=1,Table2[[#This Row],[Thursday]],Table2[[#This Row],[Friday]])) -> OFF | G3: =IFERROR(_xlfn.LET(_xlpm.s,SUBSTITUTE(IF(Table2[[#This Row],[Column1]]=1,Table2[[#This Row],[Friday]],Table2[[#This Row],[Saturday]])," ",""),IF(_xlpm.s="OFF","OFF",TEXT(MOD(TIMEVALUE(_xlfn.TEXTBEFORE(_xlpm.s,"-"))+0.5,1),"hh:mm")&" - "&TEXT(MOD(TIMEVALUE(_xlfn.TEXTAFTER(_xlpm.s,"-"))+0.5,1),"hh:mm"))),IF(Table2[[#This Row],[Column1]]=1,Table2[[#This Row],[Friday]],Table2[[#This Row],[Saturday]])) -> 13:00 - 00:00 | H3: =IFERROR(_xlfn.LET(_xlpm.s,SUBSTITUTE(IF(Table2[[#This Row],[Column1]]=1,Table2[[#This Row],[Saturday]],Table2[[#This Row],[Sunday]])," ",""),IF(_xlpm.s="OFF","OFF",TEXT(MOD(TIMEVALUE(_xlfn.TEXTBEFORE(_xlpm.s,"-"))+0.5,1),"hh:mm")&" - "&TEXT(MOD(TIMEVALUE(_xlfn.TEXTAFTER(_xlpm.s,"-"))+0.5,1),"hh:mm"))),IF(Table2[[#This Row],[Column1]]=1,Table2[[#This Row],[Saturday]],Table2[[#This Row],[Sunday]])) -> 13:00 - 00:00 | I3: =_xlfn.TEXTJOIN(" - ",TRUE, IF(B3="OFF","Mon",""), IF(C3="OFF","Tue",""), IF(D3="OFF","Wed",""), IF(E3="OFF","Thu",""), IF(F3="OFF","Fri",""), IF(G3="OFF","Sat",""), IF(H3="OFF","Sun","")) -> Wed - Thu - Fri | J3: =MOD(Table2[[#This Row],[Break 1]]+TIME(12,0,0),1) -> 0.625 | K3: =MOD(Table2[[#This Row],[Break 2]]+TIME(12,0,0),1) -> 0.70833333 | L3: =MOD(Table2[[#This Row],[Lunch]]+TIME(12,0,0),1) -> 0.83333333 | M3: =MOD(Table2[[#This Row],[Break 3]]+TIME(12,0,0),1) -> 0.95833333 | N3: =Table2[[#This Row],[Supervisor]] -> Chris Borromeo | O3: =TEXT(TIMEVALUE(LEFT(Table2[[#This Row],[EST SHIFT]],5))+12/24,"hh:mm") & " - " & TEXT(TIMEVALUE(RIGHT(Table2[[#This Row],[EST SHIFT]],5))+12/24,"hh:mm") -> 13:00 - 00:00 | P3: =IF(TIMEVALUE(LEFT(O3,FIND("-",O3)-1))>=12/24,0,1) -> 0
A4: =Table2[[#This Row],[Name]] -> Aireen Balanon | B4: =IFERROR(_xlfn.LET(_xlpm.s,SUBSTITUTE(IF(Table2[[#This Row],[Column1]]=1,Table2[[#This Row],[Sunday]],Table2[[#This Row],[Monday]])," ",""),IF(_xlpm.s="OFF","OFF",TEXT(MOD(TIMEVALUE(_xlfn.TEXTBEFORE(_xlpm.s,"-"))+0.5,1),"hh:mm")&" - "&TEXT(MOD(TIMEVALUE(_xlfn.TEXTAFTER(_xlpm.s,"-"))+0.5,1),"hh:mm"))),IF(Table2[[#This Row],[Column1]]=1,Table2[[#This Row],[Sunday]],Table2[[#This Row],[Monday]])) -> 14:00 - 01:00 | C4: =IFERROR(_xlfn.LET(_xlpm.s,SUBSTITUTE(IF(Table2[[#This Row],[Column1]]=1,Table2[[#This Row],[Monday]],Table2[[#This Row],[Tuesday]])," ",""),IF(_xlpm.s="OFF","OFF",TEXT(MOD(TIMEVALUE(_xlfn.TEXTBEFORE(_xlpm.s,"-"))+0.5,1),"hh:mm")&" - "&TEXT(MOD(TIMEVALUE(_xlfn.TEXTAFTER(_xlpm.s,"-"))+0.5,1),"hh:mm"))),IF(Table2[[#This Row],[Column1]]=1,Table2[[#This Row],[Monday]],Table2[[#This Row],[Tuesday]])) -> 14:00 - 01:00 | D4: =IFERROR(_xlfn.LET(_xlpm.s,SUBSTITUTE(IF(Table2[[#This Row],[Column1]]=1,Table2[[#This Row],[Tuesday]],Table2[[#This Row],[Wednesday]])," ",""),IF(_xlpm.s="OFF","OFF",TEXT(MOD(TIMEVALUE(_xlfn.TEXTBEFORE(_xlpm.s,"-"))+0.5,1),"hh:mm")&" - "&TEXT(MOD(TIMEVALUE(_xlfn.TEXTAFTER(_xlpm.s,"-"))+0.5,1),"hh:mm"))),IF(Table2[[#This Row],[Column1]]=1,Table2[[#This Row],[Tuesday]],Table2[[#This Row],[Wednesday]])) -> OFF | E4: =IFERROR(_xlfn.LET(_xlpm.s,SUBSTITUTE(IF(Table2[[#This Row],[Column1]]=1,Table2[[#This Row],[Wednesday]],Table2[[#This Row],[Thursday]])," ",""),IF(_xlpm.s="OFF","OFF",TEXT(MOD(TIMEVALUE(_xlfn.TEXTBEFORE(_xlpm.s,"-"))+0.5,1),"hh:mm")&" - "&TEXT(MOD(TIMEVALUE(_xlfn.TEXTAFTER(_xlpm.s,"-"))+0.5,1),"hh:mm"))),IF(Table2[[#This Row],[Column1]]=1,Table2[[#This Row],[Wednesday]],Table2[[#This Row],[Thursday]])) -> OFF | F4: =IFERROR(_xlfn.LET(_xlpm.s,SUBSTITUTE(IF(Table2[[#This Row],[Column1]]=1,Table2[[#This Row],[Thursday]],Table2[[#This Row],[Friday]])," ",""),IF(_xlpm.s="OFF","OFF",TEXT(MOD(TIMEVALUE(_xlfn.TEXTBEFORE(_xlpm.s,"-"))+0.5,1),"hh:mm")&" - "&TEXT(MOD(TIMEVALUE(_xlfn.TEXTAFTER(_xlpm.s,"-"))+0.5,1),"hh:mm"))),IF(Table2[[#This Row],[Column1]]=1,Table2[[#This Row],[Thursday]],Table2[[#This Row],[Friday]])) -> OFF | G4: =IFERROR(_xlfn.LET(_xlpm.s,SUBSTITUTE(IF(Table2[[#This Row],[Column1]]=1,Table2[[#This Row],[Friday]],Table2[[#This Row],[Saturday]])," ",""),IF(_xlpm.s="OFF","OFF",TEXT(MOD(TIMEVALUE(_xlfn.TEXTBEFORE(_xlpm.s,"-"))+0.5,1),"hh:mm")&" - "&TEXT(MOD(TIMEVALUE(_xlfn.TEXTAFTER(_xlpm.s,"-"))+0.5,1),"hh:mm"))),IF(Table2[[#This Row],[Column1]]=1,Table2[[#This Row],[Friday]],Table2[[#This Row],[Saturday]])) -> 14:00 - 01:00 | H4: =IFERROR(_xlfn.LET(_xlpm.s,SUBSTITUTE(IF(Table2[[#This Row],[Column1]]=1,Table2[[#This Row],[Saturday]],Table2[[#This Row],[Sunday]])," ",""),IF(_xlpm.s="OFF","OFF",TEXT(MOD(TIMEVALUE(_xlfn.TEXTBEFORE(_xlpm.s,"-"))+0.5,1),"hh:mm")&" - "&TEXT(MOD(TIMEVALUE(_xlfn.TEXTAFTER(_xlpm.s,"-"))+0.5,1),"hh:mm"))),IF(Table2[[#This Row],[Column1]]=1,Table2[[#This Row],[Saturday]],Table2[[#This Row],[Sunday]])) -> 14:00 - 01:00 | I4: =_xlfn.TEXTJOIN(" - ",TRUE, IF(B4="OFF","Mon",""), IF(C4="OFF","Tue",""), IF(D4="OFF","Wed",""), IF(E4="OFF","Thu",""), IF(F4="OFF","Fri",""), IF(G4="OFF","Sat",""), IF(H4="OFF","Sun","")) -> Wed - Thu - Fri | J4: =MOD(Table2[[#This Row],[Break 1]]+TIME(12,0,0),1) -> 0.66666667 | K4: =MOD(Table2[[#This Row],[Break 2]]+TIME(12,0,0),1) -> 0.89583333 | L4: =MOD(Table2[[#This Row],[Lunch]]+TIME(12,0,0),1) -> 0.80208333 | M4: =MOD(Table2[[#This Row],[Break 3]]+TIME(12,0,0),1) -> 0.98958333 | N4: =Table2[[#This Row],[Supervisor]] -> Remmo Panaligan | O4: =TEXT(TIMEVALUE(LEFT(Table2[[#This Row],[EST SHIFT]],5))+12/24,"hh:mm") & " - " & TEXT(TIMEVALUE(RIGHT(Table2[[#This Row],[EST SHIFT]],5))+12/24,"hh:mm") -> 14:00 - 01:00 | P4: =IF(TIMEVALUE(LEFT(O4,FIND("-",O4)-1))>=12/24,0,1) -> 0
A5: =Table2[[#This Row],[Name]] -> Jeffryl Joe Pardillo | B5: =IFERROR(_xlfn.LET(_xlpm.s,SUBSTITUTE(IF(Table2[[#This Row],[Column1]]=1,Table2[[#This Row],[Sunday]],Table2[[#This Row],[Monday]])," ",""),IF(_xlpm.s="OFF","OFF",TEXT(MOD(TIMEVALUE(_xlfn.TEXTBEFORE(_xlpm.s,"-"))+0.5,1),"hh:mm")&" - "&TEXT(MOD(TIMEVALUE(_xlfn.TEXTAFTER(_xlpm.s,"-"))+0.5,1),"hh:mm"))),IF(Table2[[#This Row],[Column1]]=1,Table2[[#This Row],[Sunday]],Table2[[#This Row],[Monday]])) -> 15:00 - 02:00 | C5: =IFERROR(_xlfn.LET(_xlpm.s,SUBSTITUTE(IF(Table2[[#This Row],[Column1]]=1,Table2[[#This Row],[Monday]],Table2[[#This Row],[Tuesday]])," ",""),IF(_xlpm.s="OFF","OFF",TEXT(MOD(TIMEVALUE(_xlfn.TEXTBEFORE(_xlpm.s,"-"))+0.5,1),"hh:mm")&" - "&TEXT(MOD(TIMEVALUE(_xlfn.TEXTAFTER(_xlpm.s,"-"))+0.5,1),"hh:mm"))),IF(Table2[[#This Row],[Column1]]=1,Table2[[#This Row],[Monday]],Table2[[#This Row],[Tuesday]])) -> 15:00 - 02:00 | D5: =IFERROR(_xlfn.LET(_xlpm.s,SUBSTITUTE(IF(Table2[[#This Row],[Column1]]=1,Table2[[#This Row],[Tuesday]],Table2[[#This Row],[Wednesday]])," ",""),IF(_xlpm.s="OFF","OFF",TEXT(MOD(TIMEVALUE(_xlfn.TEXTBEFORE(_xlpm.s,"-"))+0.5,1),"hh:mm")&" - "&TEXT(MOD(TIMEVALUE(_xlfn.TEXTAFTER(_xlpm.s,"-"))+0.5,1),"hh:mm"))),IF(Table2[[#This Row],[Column1]]=1,Table2[[#This Row],[Tuesday]],Table2[[#This Row],[Wednesday]])) -> 15:00 - 02:00 | E5: =IFERROR(_xlfn.LET(_xlpm.s,SUBSTITUTE(IF(Table2[[#This Row],[Column1]]=1,Table2[[#This Row],[Wednesday]],Table2[[#This Row],[Thursday]])," ",""),IF(_xlpm.s="OFF","OFF",TEXT(MOD(TIMEVALUE(_xlfn.TEXTBEFORE(_xlpm.s,"-"))+0.5,1),"hh:mm")&" - "&TEXT(MOD(TIMEVALUE(_xlfn.TEXTAFTER(_xlpm.s,"-"))+0.5,1),"hh:mm"))),IF(Table2[[#This Row],[Column1]]=1,Table2[[#This Row],[Wednesday]],Table2[[#This Row],[Thursday]])) -> OFF | F5: =IFERROR(_xlfn.LET(_xlpm.s,SUBSTITUTE(IF(Table2[[#This Row],[Column1]]=1,Table2[[#This Row],[Thursday]],Table2[[#This Row],[Friday]])," ",""),IF(_xlpm.s="OFF","OFF",TEXT(MOD(TIMEVALUE(_xlfn.TEXTBEFORE(_xlpm.s,"-"))+0.5,1),"hh:mm")&" - "&TEXT(MOD(TIMEVALUE(_xlfn.TEXTAFTER(_xlpm.s,"-"))+0.5,1),"hh:mm"))),IF(Table2[[#This Row],[Column1]]=1,Table2[[#This Row],[Thursday]],Table2[[#This Row],[Friday]])) -> OFF | G5: =IFERROR(_xlfn.LET(_xlpm.s,SUBSTITUTE(IF(Table2[[#This Row],[Column1]]=1,Table2[[#This Row],[Friday]],Table2[[#This Row],[Saturday]])," ",""),IF(_xlpm.s="OFF","OFF",TEXT(MOD(TIMEVALUE(_xlfn.TEXTBEFORE(_xlpm.s,"-"))+0.5,1),"hh:mm")&" - "&TEXT(MOD(TIMEVALUE(_xlfn.TEXTAFTER(_xlpm.s,"-"))+0.5,1),"hh:mm"))),IF(Table2[[#This Row],[Column1]]=1,Table2[[#This Row],[Friday]],Table2[[#This Row],[Saturday]])) -> OFF | H5: =IFERROR(_xlfn.LET(_xlpm.s,SUBSTITUTE(IF(Table2[[#This Row],[Column1]]=1,Table2[[#This Row],[Saturday]],Table2[[#This Row],[Sunday]])," ",""),IF(_xlpm.s="OFF","OFF",TEXT(MOD(TIMEVALUE(_xlfn.TEXTBEFORE(_xlpm.s,"-"))+0.5,1),"hh:mm")&" - "&TEXT(MOD(TIMEVALUE(_xlfn.TEXTAFTER(_xlpm.s,"-"))+0.5,1),"hh:mm"))),IF(Table2[[#This Row],[Column1]]=1,Table2[[#This Row],[Saturday]],Table2[[#This Row],[Sunday]])) -> 15:00 - 02:00 | I5: =_xlfn.TEXTJOIN(" - ",TRUE, IF(B5="OFF","Mon",""), IF(C5="OFF","Tue",""), IF(D5="OFF","Wed",""), IF(E5="OFF","Thu",""), IF(F5="OFF","Fri",""), IF(G5="OFF","Sat",""), IF(H5="OFF","Sun","")) -> Thu - Fri - Sat | J5: =MOD(Table2[[#This Row],[Break 1]]+TIME(12,0,0),1) -> 0.69791667 | K5: =MOD(Table2[[#This Row],[Break 2]]+TIME(12,0,0),1) -> 0.91666667 | L5: =MOD(Table2[[#This Row],[Lunch]]+TIME(12,0,0),1) -> 0.79166667 | M5: =MOD(Table2[[#This Row],[Break 3]]+TIME(12,0,0),1) -> 0.020833333 | N5: =Table2[[#This Row],[Supervisor]] -> Christopher Rodas | O5: =TEXT(TIMEVALUE(LEFT(Table2[[#This Row],[EST SHIFT]],5))+12/24,"hh:mm") & " - " & TEXT(TIMEVALUE(RIGHT(Table2[[#This Row],[EST SHIFT]],5))+12/24,"hh:mm") -> 15:00 - 02:00 | P5: =IF(TIMEVALUE(LEFT(O5,FIND("-",O5)-1))>=12/24,0,1) -> 0
A6: =Table2[[#This Row],[Name]] -> Chris Paul Dalut | B6: =IFERROR(_xlfn.LET(_xlpm.s,SUBSTITUTE(IF(Table2[[#This Row],[Column1]]=1,Table2[[#This Row],[Sunday]],Table2[[#This Row],[Monday]])," ",""),IF(_xlpm.s="OFF","OFF",TEXT(MOD(TIMEVALUE(_xlfn.TEXTBEFORE(_xlpm.s,"-"))+0.5,1),"hh:mm")&" - "&TEXT(MOD(TIMEVALUE(_xlfn.TEXTAFTER(_xlpm.s,"-"))+0.5,1),"hh:mm"))),IF(Table2[[#This Row],[Column1]]=1,Table2[[#This Row],[Sunday]],Table2[[#This Row],[Monday]])) -> 16:00 - 03:00 | C6: =IFERROR(_xlfn.LET(_xlpm.s,SUBSTITUTE(IF(Table2[[#This Row],[Column1]]=1,Table2[[#This Row],[Monday]],Table2[[#This Row],[Tuesday]])," ",""),IF(_xlpm.s="OFF","OFF",TEXT(MOD(TIMEVALUE(_xlfn.TEXTBEFORE(_xlpm.s,"-"))+0.5,1),"hh:mm")&" - "&TEXT(MOD(TIMEVALUE(_xlfn.TEXTAFTER(_xlpm.s,"-"))+0.5,1),"hh:mm"))),IF(Table2[[#This Row],[Column1]]=1,Table2[[#This Row],[Monday]],Table2[[#This Row],[Tuesday]])) -> 16:00 - 03:00 | D6: =IFERROR(_xlfn.LET(_xlpm.s,SUBSTITUTE(IF(Table2[[#This Row],[Column1]]=1,Table2[[#This Row],[Tuesday]],Table2[[#This Row],[Wednesday]])," ",""),IF(_xlpm.s="OFF","OFF",TEXT(MOD(TIMEVALUE(_xlfn.TEXTBEFORE(_xlpm.s,"-"))+0.5,1),"hh:mm")&" - "&TEXT(MOD(TIMEVALUE(_xlfn.TEXTAFTER(_xlpm.s,"-"))+0.5,1),"hh:mm"))),IF(Table2[[#This Row],[Column1]]=1,Table2[[#This Row],[Tuesday]],Table2[[#This Row],[Wednesday]])) -> OFF | E6: =IFERROR(_xlfn.LET(_xlpm.s,SUBSTITUTE(IF(Table2[[#This Row],[Column1]]=1,Table2[[#This Row],[Wednesday]],Table2[[#This Row],[Thursday]])," ",""),IF(_xlpm.s="OFF","OFF",TEXT(MOD(TIMEVALUE(_xlfn.TEXTBEFORE(_xlpm.s,"-"))+0.5,1),"hh:mm")&" - "&TEXT(MOD(TIMEVALUE(_xlfn.TEXTAFTER(_xlpm.s,"-"))+0.5,1),"hh:mm"))),IF(Table2[[#This Row],[Column1]]=1,Table2[[#This Row],[Wednesday]],Table2[[#This Row],[Thursday]])) -> 16:00 - 03:00 | F6: =IFERROR(_xlfn.LET(_xlpm.s,SUBSTITUTE(IF(Table2[[#This Row],[Column1]]=1,Table2[[#This Row],[Thursday]],Table2[[#This Row],[Friday]])," ",""),IF(_xlpm.s="OFF","OFF",TEXT(MOD(TIMEVALUE(_xlfn.TEXTBEFORE(_xlpm.s,"-"))+0.5,1),"hh:mm")&" - "&TEXT(MOD(TIMEVALUE(_xlfn.TEXTAFTER(_xlpm.s,"-"))+0.5,1),"hh:mm"))),IF(Table2[[#This Row],[Column1]]=1,Table2[[#This Row],[Thursday]],Table2[[#This Row],[Friday]])) -> 16:00 - 03:00 | G6: =IFERROR(_xlfn.LET(_xlpm.s,SUBSTITUTE(IF(Table2[[#This Row],[Column1]]=1,Table2[[#This Row],[Friday]],Table2[[#This Row],[Saturday]])," ",""),IF(_xlpm.s="OFF","OFF",TEXT(MOD(TIMEVALUE(_xlfn.TEXTBEFORE(_xlpm.s,"-"))+0.5,1),"hh:mm")&" - "&TEXT(MOD(TIMEVALUE(_xlfn.TEXTAFTER(_xlpm.s,"-"))+0.5,1),"hh:mm"))),IF(Table2[[#This Row],[Column1]]=1,Table2[[#This Row],[Friday]],Table2[[#This Row],[Saturday]])) -> OFF | H6: =IFERROR(_xlfn.LET(_xlpm.s,SUBSTITUTE(IF(Table2[[#This Row],[Column1]]=1,Table2[[#This Row],[Saturday]],Table2[[#This Row],[Sunday]])," ",""),IF(_xlpm.s="OFF","OFF",TEXT(MOD(TIMEVALUE(_xlfn.TEXTBEFORE(_xlpm.s,"-"))+0.5,1),"hh:mm")&" - "&TEXT(MOD(TIMEVALUE(_xlfn.TEXTAFTER(_xlpm.s,"-"))+0.5,1),"hh:mm"))),IF(Table2[[#This Row],[Column1]]=1,Table2[[#This Row],[Saturday]],Table2[[#This Row],[Sunday]])) -> OFF | I6: =_xlfn.TEXTJOIN(" - ",TRUE, IF(B6="OFF","Mon",""), IF(C6="OFF","Tue",""), IF(D6="OFF","Wed",""), IF(E6="OFF","Thu",""), IF(F6="OFF","Fri",""), IF(G6="OFF","Sat",""), IF(H6="OFF","Sun","")) -> Wed - Sat - Sun | J6: =MOD(Table2[[#This Row],[Break 1]]+TIME(12,0,0),1) -> 0.73958333 | K6: =MOD(Table2[[#This Row],[Break 2]]+TIME(12,0,0),1) -> 0.97916667 | L6: =MOD(Table2[[#This Row],[Lunch]]+TIME(12,0,0),1) -> 0.85416667 | M6: =MOD(Table2[[#This Row],[Break 3]]+TIME(12,0,0),1) -> 0.083333333 | N6: =Table2[[#This Row],[Supervisor]] -> Anmecha Valencia | O6: =TEXT(TIMEVALUE(LEFT(Table2[[#This Row],[EST SHIFT]],5))+12/24,"hh:mm") & " - " & TEXT(TIMEVALUE(RIGHT(Table2[[#This Row],[EST SHIFT]],5))+12/24,"hh:mm") -> 16:00 - 03:00 | P6: =IF(TIMEVALUE(LEFT(O6,FIND("-",O6)-1))>=12/24,0,1) -> 0
A7: =Table2[[#This Row],[Name]] -> Jackyleen Caballero | B7: =IFERROR(_xlfn.LET(_xlpm.s,SUBSTITUTE(IF(Table2[[#This Row],[Column1]]=1,Table2[[#This Row],[Sunday]],Table2[[#This Row],[Monday]])," ",""),IF(_xlpm.s="OFF","OFF",TEXT(MOD(TIMEVALUE(_xlfn.TEXTBEFORE(_xlpm.s,"-"))+0.5,1),"hh:mm")&" - "&TEXT(MOD(TIMEVALUE(_xlfn.TEXTAFTER(_xlpm.s,"-"))+0.5,1),"hh:mm"))),IF(Table2[[#This Row],[Column1]]=1,Table2[[#This Row],[Sunday]],Table2[[#This Row],[Monday]])) -> 18:00 - 05:00 | C7: =IFERROR(_xlfn.LET(_xlpm.s,SUBSTITUTE(IF(Table2[[#This Row],[Column1]]=1,Table2[[#This Row],[Monday]],Table2[[#This Row],[Tuesday]])," ",""),IF(_xlpm.s="OFF","OFF",TEXT(MOD(TIMEVALUE(_xlfn.TEXTBEFORE(_xlpm.s,"-"))+0.5,1),"hh:mm")&" - "&TEXT(MOD(TIMEVALUE(_xlfn.TEXTAFTER(_xlpm.s,"-"))+0.5,1),"hh:mm"))),IF(Table2[[#This Row],[Column1]]=1,Table2[[#This Row],[Monday]],Table2[[#This Row],[Tuesday]])) -> 18:00 - 05:00 | D7: =IFERROR(_xlfn.LET(_xlpm.s,SUBSTITUTE(IF(Table2[[#This Row],[Column1]]=1,Table2[[#This Row],[Tuesday]],Table2[[#This Row],[Wednesday]])," ",""),IF(_xlpm.s="OFF","OFF",TEXT(MOD(TIMEVALUE(_xlfn.TEXTBEFORE(_xlpm.s,"-"))+0.5,1),"hh:mm")&" - "&TEXT(MOD(TIMEVALUE(_xlfn.TEXTAFTER(_xlpm.s,"-"))+0.5,1),"hh:mm"))),IF(Table2[[#This Row],[Column1]]=1,Table2[[#This Row],[Tuesday]],Table2[[#This Row],[Wednesday]])) -> 18:00 - 05:00 | E7: =IFERROR(_xlfn.LET(_xlpm.s,SUBSTITUTE(IF(Table2[[#This Row],[Column1]]=1,Table2[[#This Row],[Wednesday]],Table2[[#This Row],[Thursday]])," ",""),IF(_xlpm.s="OFF","OFF",TEXT(MOD(TIMEVALUE(_xlfn.TEXTBEFORE(_xlpm.s,"-"))+0.5,1),"hh:mm")&" - "&TEXT(MOD(TIMEVALUE(_xlfn.TEXTAFTER(_xlpm.s,"-"))+0.5,1),"hh:mm"))),IF(Table2[[#This Row],[Column1]]=1,Table2[[#This Row],[Wednesday]],Table2[[#This Row],[Thursday]])) -> OFF | F7: =IFERROR(_xlfn.LET(_xlpm.s,SUBSTITUTE(IF(Table2[[#This Row],[Column1]]=1,Table2[[#This Row],[Thursday]],Table2[[#This Row],[Friday]])," ",""),IF(_xlpm.s="OFF","OFF",TEXT(MOD(TIMEVALUE(_xlfn.TEXTBEFORE(_xlpm.s,"-"))+0.5,1),"hh:mm")&" - "&TEXT(MOD(TIMEVALUE(_xlfn.TEXTAFTER(_xlpm.s,"-"))+0.5,1),"hh:mm"))),IF(Table2[[#This Row],[Column1]]=1,Table2[[#This Row],[Thursday]],Table2[[#This Row],[Friday]])) -> OFF | G7: =IFERROR(_xlfn.LET(_xlpm.s,SUBSTITUTE(IF(Table2[[#This Row],[Column1]]=1,Table2[[#This Row],[Friday]],Table2[[#This Row],[Saturday]])," ",""),IF(_xlpm.s="OFF","OFF",TEXT(MOD(TIMEVALUE(_xlfn.TEXTBEFORE(_xlpm.s,"-"))+0.5,1),"hh:mm")&" - "&TEXT(MOD(TIMEVALUE(_xlfn.TEXTAFTER(_xlpm.s,"-"))+0.5,1),"hh:mm"))),IF(Table2[[#This Row],[Column1]]=1,Table2[[#This Row],[Friday]],Table2[[#This Row],[Saturday]])) -> OFF | H7: =IFERROR(_xlfn.LET(_xlpm.s,SUBSTITUTE(IF(Table2[[#This Row],[Column1]]=1,Table2[[#This Row],[Saturday]],Table2[[#This Row],[Sunday]])," ",""),IF(_xlpm.s="OFF","OFF",TEXT(MOD(TIMEVALUE(_xlfn.TEXTBEFORE(_xlpm.s,"-"))+0.5,1),"hh:mm")&" - "&TEXT(MOD(TIMEVALUE(_xlfn.TEXTAFTER(_xlpm.s,"-"))+0.5,1),"hh:mm"))),IF(Table2[[#This Row],[Column1]]=1,Table2[[#This Row],[Saturday]],Table2[[#This Row],[Sunday]])) -> 18:00 - 05:00 | I7: =_xlfn.TEXTJOIN(" - ",TRUE, IF(B7="OFF","Mon",""), IF(C7="OFF","Tue",""), IF(D7="OFF","Wed",""), IF(E7="OFF","Thu",""), IF(F7="OFF","Fri",""), IF(G7="OFF","Sat",""), IF(H7="OFF","Sun","")) -> Thu - Fri - Sat | J7: =MOD(Table2[[#This Row],[Break 1]]+TIME(12,0,0),1) -> 0.84375 | K7: =MOD(Table2[[#This Row],[Break 2]]+TIME(12,0,0),1) -> 0.083333333 | L7: =MOD(Table2[[#This Row],[Lunch]]+TIME(12,0,0),1) -> 0.95833333 | M7: =MOD(Table2[[#This Row],[Break 3]]+TIME(12,0,0),1) -> 0.1875 | N7: =Table2[[#This Row],[Supervisor]] -> Christopher Rodas | O7: =TEXT(TIMEVALUE(LEFT(Table2[[#This Row],[EST SHIFT]],5))+12/24,"hh:mm") & " - " & TEXT(TIMEVALUE(RIGHT(Table2[[#This Row],[EST SHIFT]],5))+12/24,"hh:mm") -> 18:00 - 05:00 | P7: =IF(TIMEVALUE(LEFT(O7,FIND("-",O7)-1))>=12/24,0,1) -> 0
A8: =Table2[[#This Row],[Name]] -> Mark Raymond Mangaser Jr | B8: =IFERROR(_xlfn.LET(_xlpm.s,SUBSTITUTE(IF(Table2[[#This Row],[Column1]]=1,Table2[[#This Row],[Sunday]],Table2[[#This Row],[Monday]])," ",""),IF(_xlpm.s="OFF","OFF",TEXT(MOD(TIMEVALUE(_xlfn.TEXTBEFORE(_xlpm.s,"-"))+0.5,1),"hh:mm")&" - "&TEXT(MOD(TIMEVALUE(_xlfn.TEXTAFTER(_xlpm.s,"-"))+0.5,1),"hh:mm"))),IF(Table2[[#This Row],[Column1]]=1,Table2[[#This Row],[Sunday]],Table2[[#This Row],[Monday]])) -> 18:00 - 05:00 | C8: =IFERROR(_xlfn.LET(_xlpm.s,SUBSTITUTE(IF(Table2[[#This Row],[Column1]]=1,Table2[[#This Row],[Monday]],Table2[[#This Row],[Tuesday]])," ",""),IF(_xlpm.s="OFF","OFF",TEXT(MOD(TIMEVALUE(_xlfn.TEXTBEFORE(_xlpm.s,"-"))+0.5,1),"hh:mm")&" - "&TEXT(MOD(TIMEVALUE(_xlfn.TEXTAFTER(_xlpm.s,"-"))+0.5,1),"hh:mm"))),IF(Table2[[#This Row],[Column1]]=1,Table2[[#This Row],[Monday]],Table2[[#This Row],[Tuesday]])) -> 18:00 - 05:00 | D8: =IFERROR(_xlfn.LET(_xlpm.s,SUBSTITUTE(IF(Table2[[#This Row],[Column1]]=1,Table2[[#This Row],[Tuesday]],Table2[[#This Row],[Wednesday]])," ",""),IF(_xlpm.s="OFF","OFF",TEXT(MOD(TIMEVALUE(_xlfn.TEXTBEFORE(_xlpm.s,"-"))+0.5,1),"hh:mm")&" - "&TEXT(MOD(TIMEVALUE(_xlfn.TEXTAFTER(_xlpm.s,"-"))+0.5,1),"hh:mm"))),IF(Table2[[#This Row],[Column1]]=1,Table2[[#This Row],[Tuesday]],Table2[[#This Row],[Wednesday]])) -> OFF | E8: =IFERROR(_xlfn.LET(_xlpm.s,SUBSTITUTE(IF(Table2[[#This Row],[Column1]]=1,Table2[[#This Row],[Wednesday]],Table2[[#This Row],[Thursday]])," ",""),IF(_xlpm.s="OFF","OFF",TEXT(MOD(TIMEVALUE(_xlfn.TEXTBEFORE(_xlpm.s,"-"))+0.5,1),"hh:mm")&" - "&TEXT(MOD(TIMEVALUE(_xlfn.TEXTAFTER(_xlpm.s,"-"))+0.5,1),"hh:mm"))),IF(Table2[[#This Row],[Column1]]=1,Table2[[#This Row],[Wednesday]],Table2[[#This Row],[Thursday]])) -> OFF | F8: =IFERROR(_xlfn.LET(_xlpm.s,SUBSTITUTE(IF(Table2[[#This Row],[Column1]]=1,Table2[[#This Row],[Thursday]],Table2[[#This Row],[Friday]])," ",""),IF(_xlpm.s="OFF","OFF",TEXT(MOD(TIMEVALUE(_xlfn.TEXTBEFORE(_xlpm.s,"-"))+0.5,1),"hh:mm")&" - "&TEXT(MOD(TIMEVALUE(_xlfn.TEXTAFTER(_xlpm.s,"-"))+0.5,1),"hh:mm"))),IF(Table2[[#This Row],[Column1]]=1,Table2[[#This Row],[Thursday]],Table2[[#This Row],[Friday]])) -> OFF | G8: =IFERROR(_xlfn.LET(_xlpm.s,SUBSTITUTE(IF(Table2[[#This Row],[Column1]]=1,Table2[[#This Row],[Friday]],Table2[[#This Row],[Saturday]])," ",""),IF(_xlpm.s="OFF","OFF",TEXT(MOD(TIMEVALUE(_xlfn.TEXTBEFORE(_xlpm.s,"-"))+0.5,1),"hh:mm")&" - "&TEXT(MOD(TIMEVALUE(_xlfn.TEXTAFTER(_xlpm.s,"-"))+0.5,1),"hh:mm"))),IF(Table2[[#This Row],[Column1]]=1,Table2[[#This Row],[Friday]],Table2[[#This Row],[Saturday]])) -> 18:00 - 05:00 | H8: =IFERROR(_xlfn.LET(_xlpm.s,SUBSTITUTE(IF(Table2[[#This Row],[Column1]]=1,Table2[[#This Row],[Saturday]],Table2[[#This Row],[Sunday]])," ",""),IF(_xlpm.s="OFF","OFF",TEXT(MOD(TIMEVALUE(_xlfn.TEXTBEFORE(_xlpm.s,"-"))+0.5,1),"hh:mm")&" - "&TEXT(MOD(TIMEVALUE(_xlfn.TEXTAFTER(_xlpm.s,"-"))+0.5,1),"hh:mm"))),IF(Table2[[#This Row],[Column1]]=1,Table2[[#This Row],[Saturday]],Table2[[#This Row],[Sunday]])) -> 18:00 - 05:00 | I8: =_xlfn.TEXTJOIN(" - ",TRUE, IF(B8="OFF","Mon",""), IF(C8="OFF","Tue",""), IF(D8="OFF","Wed",""), IF(E8="OFF","Thu",""), IF(F8="OFF","Fri",""), IF(G8="OFF","Sat",""), IF(H8="OFF","Sun","")) -> Wed - Thu - Fri | J8: =MOD(Table2[[#This Row],[Break 1]]+TIME(12,0,0),1) -> 0.83333333 | K8: =MOD(Table2[[#This Row],[Break 2]]+TIME(12,0,0),1) -> 0.052083333 | L8: =MOD(Table2[[#This Row],[Lunch]]+TIME(12,0,0),1) -> 0.92708333 | M8: =MOD(Table2[[#This Row],[Break 3]]+TIME(12,0,0),1) -> 0.15625 | N8: =Table2[[#This Row],[Supervisor]] -> Remmo Panaligan | O8: =TEXT(TIMEVALUE(LEFT(Table2[[#This Row],[EST SHIFT]],5))+12/24,"hh:mm") & " - " & TEXT(TIMEVALUE(RIGHT(Table2[[#This Row],[EST SHIFT]],5))+12/24,"hh:mm") -> 18:00 - 05:00 | P8: =IF(TIMEVALUE(LEFT(O8,FIND("-",O8)-1))>=12/24,0,1) -> 0
A9: =Table2[[#This Row],[Name]] -> Raquela Nicole Lareta | B9: =IFERROR(_xlfn.LET(_xlpm.s,SUBSTITUTE(IF(Table2[[#This Row],[Column1]]=1,Table2[[#This Row],[Sunday]],Table2[[#This Row],[Monday]])," ",""),IF(_xlpm.s="OFF","OFF",TEXT(MOD(TIMEVALUE(_xlfn.TEXTBEFORE(_xlpm.s,"-"))+0.5,1),"hh:mm")&" - "&TEXT(MOD(TIMEVALUE(_xlfn.TEXTAFTER(_xlpm.s,"-"))+0.5,1),"hh:mm"))),IF(Table2[[#This Row],[Column1]]=1,Table2[[#This Row],[Sunday]],Table2[[#This Row],[Monday]])) -> 18:00 - 05:00 | C9: =IFERROR(_xlfn.LET(_xlpm.s,SUBSTITUTE(IF(Table2[[#This Row],[Column1]]=1,Table2[[#This Row],[Monday]],Table2[[#This Row],[Tuesday]])," ",""),IF(_xlpm.s="OFF","OFF",TEXT(MOD(TIMEVALUE(_xlfn.TEXTBEFORE(_xlpm.s,"-"))+0.5,1),"hh:mm")&" - "&TEXT(MOD(TIMEVALUE(_xlfn.TEXTAFTER(_xlpm.s,"-"))+0.5,1),"hh:mm"))),IF(Table2[[#This Row],[Column1]]=1,Table2[[#This Row],[Monday]],Table2[[#This Row],[Tuesday]])) -> 18:00 - 05:00 | D9: =IFERROR(_xlfn.LET(_xlpm.s,SUBSTITUTE(IF(Table2[[#This Row],[Column1]]=1,Table2[[#This Row],[Tuesday]],Table2[[#This Row],[Wednesday]])," ",""),IF(_xlpm.s="OFF","OFF",TEXT(MOD(TIMEVALUE(_xlfn.TEXTBEFORE(_xlpm.s,"-"))+0.5,1),"hh:mm")&" - "&TEXT(MOD(TIMEVALUE(_xlfn.TEXTAFTER(_xlpm.s,"-"))+0.5,1),"hh:mm"))),IF(Table2[[#This Row],[Column1]]=1,Table2[[#This Row],[Tuesday]],Table2[[#This Row],[Wednesday]])) -> 18:00 - 05:00 | E9: =IFERROR(_xlfn.LET(_xlpm.s,SUBSTITUTE(IF(Table2[[#This Row],[Column1]]=1,Table2[[#This Row],[Wednesday]],Table2[[#This Row],[Thursday]])," ",""),IF(_xlpm.s="OFF","OFF",TEXT(MOD(TIMEVALUE(_xlfn.TEXTBEFORE(_xlpm.s,"-"))+0.5,1),"hh:mm")&" - "&TEXT(MOD(TIMEVALUE(_xlfn.TEXTAFTER(_xlpm.s,"-"))+0.5,1),"hh:mm"))),IF(Table2[[#This Row],[Column1]]=1,Table2[[#This Row],[Wednesday]],Table2[[#This Row],[Thursday]])) -> OFF | F9: =IFERROR(_xlfn.LET(_xlpm.s,SUBSTITUTE(IF(Table2[[#This Row],[Column1]]=1,Table2[[#This Row],[Thursday]],Table2[[#This Row],[Friday]])," ",""),IF(_xlpm.s="OFF","OFF",TEXT(MOD(TIMEVALUE(_xlfn.TEXTBEFORE(_xlpm.s,"-"))+0.5,1),"hh:mm")&" - "&TEXT(MOD(TIMEVALUE(_xlfn.TEXTAFTER(_xlpm.s,"-"))+0.5,1),"hh:mm"))),IF(Table2[[#This Row],[Column1]]=1,Table2[[#This Row],[Thursday]],Table2[[#This Row],[Friday]])) -> OFF | G9: =IFERROR(_xlfn.LET(_xlpm.s,SUBSTITUTE(IF(Table2[[#This Row],[Column1]]=1,Table2[[#This Row],[Friday]],Table2[[#This Row],[Saturday]])," ",""),IF(_xlpm.s="OFF","OFF",TEXT(MOD(TIMEVALUE(_xlfn.TEXTBEFORE(_xlpm.s,"-"))+0.5,1),"hh:mm")&" - "&TEXT(MOD(TIMEVALUE(_xlfn.TEXTAFTER(_xlpm.s,"-"))+0.5,1),"hh:mm"))),IF(Table2[[#This Row],[Column1]]=1,Table2[[#This Row],[Friday]],Table2[[#This Row],[Saturday]])) -> OFF | H9: =IFERROR(_xlfn.LET(_xlpm.s,SUBSTITUTE(IF(Table2[[#This Row],[Column1]]=1,Table2[[#This Row],[Saturday]],Table2[[#This Row],[Sunday]])," ",""),IF(_xlpm.s="OFF","OFF",TEXT(MOD(TIMEVALUE(_xlfn.TEXTBEFORE(_xlpm.s,"-"))+0.5,1),"hh:mm")&" - "&TEXT(MOD(TIMEVALUE(_xlfn.TEXTAFTER(_xlpm.s,"-"))+0.5,1),"hh:mm"))),IF(Table2[[#This Row],[Column1]]=1,Table2[[#This Row],[Saturday]],Table2[[#This Row],[Sunday]])) -> 18:00 - 05:00 | I9: =_xlfn.TEXTJOIN(" - ",TRUE, IF(B9="OFF","Mon",""), IF(C9="OFF","Tue",""), IF(D9="OFF","Wed",""), IF(E9="OFF","Thu",""), IF(F9="OFF","Fri",""), IF(G9="OFF","Sat",""), IF(H9="OFF","Sun","")) -> Thu - Fri - Sat | J9: =MOD(Table2[[#This Row],[Break 1]]+TIME(12,0,0),1) -> 0.83333333 | K9: =MOD(Table2[[#This Row],[Break 2]]+TIME(12,0,0),1) -> 0.041666667 | L9: =MOD(Table2[[#This Row],[Lunch]]+TIME(12,0,0),1) -> 0.91666667 | M9: =MOD(Table2[[#This Row],[Break 3]]+TIME(12,0,0),1) -> 0.15625 | N9: =Table2[[#This Row],[Supervisor]] -> Christopher Rodas | O9: =TEXT(TIMEVALUE(LEFT(Table2[[#This Row],[EST SHIFT]],5))+12/24,"hh:mm") & " - " & TEXT(TIMEVALUE(RIGHT(Table2[[#This Row],[EST SHIFT]],5))+12/24,"hh:mm") -> 18:00 - 05:00 | P9: =IF(TIMEVALUE(LEFT(O9,FIND("-",O9)-1))>=12/24,0,1) -> 0
A10: =Table2[[#This Row],[Name]] -> Giselle Florendo | B10: =IFERROR(_xlfn.LET(_xlpm.s,SUBSTITUTE(IF(Table2[[#This Row],[Column1]]=1,Table2[[#This Row],[Sunday]],Table2[[#This Row],[Monday]])," ",""),IF(_xlpm.s="OFF","OFF",TEXT(MOD(TIMEVALUE(_xlfn.TEXTBEFORE(_xlpm.s,"-"))+0.5,1),"hh:mm")&" - "&TEXT(MOD(TIMEVALUE(_xlfn.TEXTAFTER(_xlpm.s,"-"))+0.5,1),"hh:mm"))),IF(Table2[[#This Row],[Column1]]=1,Table2[[#This Row],[Sunday]],Table2[[#This Row],[Monday]])) -> 19:00 - 06:00 | C10: =IFERROR(_xlfn.LET(_xlpm.s,SUBSTITUTE(IF(Table2[[#This Row],[Column1]]=1,Table2[[#This Row],[Monday]],Table2[[#This Row],[Tuesday]])," ",""),IF(_xlpm.s="OFF","OFF",TEXT(MOD(TIMEVALUE(_xlfn.TEXTBEFORE(_xlpm.s,"-"))+0.5,1),"hh:mm")&" - "&TEXT(MOD(TIMEVALUE(_xlfn.TEXTAFTER(_xlpm.s,"-"))+0.5,1),"hh:mm"))),IF(Table2[[#This Row],[Column1]]=1,Table2[[#This Row],[Monday]],Table2[[#This Row],[Tuesday]])) -> 19:00 - 06:00 | D10: =IFERROR(_xlfn.LET(_xlpm.s,SUBSTITUTE(IF(Table2[[#This Row],[Column1]]=1,Table2[[#This Row],[Tuesday]],Table2[[#This Row],[Wednesday]])," ",""),IF(_xlpm.s="OFF","OFF",TEXT(MOD(TIMEVALUE(_xlfn.TEXTBEFORE(_xlpm.s,"-"))+0.5,1),"hh:mm")&" - "&TEXT(MOD(TIMEVALUE(_xlfn.TEXTAFTER(_xlpm.s,"-"))+0.5,1),"hh:mm"))),IF(Table2[[#This Row],[Column1]]=1,Table2[[#This Row],[Tuesday]],Table2[[#This Row],[Wednesday]])) -> 19:00 - 06:00 | E10: =IFERROR(_xlfn.LET(_xlpm.s,SUBSTITUTE(IF(Table2[[#This Row],[Column1]]=1,Table2[[#This Row],[Wednesday]],Table2[[#This Row],[Thursday]])," ",""),IF(_xlpm.s="OFF","OFF",TEXT(MOD(TIMEVALUE(_xlfn.TEXTBEFORE(_xlpm.s,"-"))+0.5,1),"hh:mm")&" - "&TEXT(MOD(TIMEVALUE(_xlfn.TEXTAFTER(_xlpm.s,"-"))+0.5,1),"hh:mm"))),IF(Table2[[#This Row],[Column1]]=1,Table2[[#This Row],[Wednesday]],Table2[[#This Row],[Thursday]])) -> 19:00 - 06:00 | F10: =IFERROR(_xlfn.LET(_xlpm.s,SUBSTITUTE(IF(Table2[[#This Row],[Column1]]=1,Table2[[#This Row],[Thursday]],Table2[[#This Row],[Friday]])," ",""),IF(_xlpm.s="OFF","OFF",TEXT(MOD(TIMEVALUE(_xlfn.TEXTBEFORE(_xlpm.s,"-"))+0.5,1),"hh:mm")&" - "&TEXT(MOD(TIMEVALUE(_xlfn.TEXTAFTER(_xlpm.s,"-"))+0.5,1),"hh:mm"))),IF(Table2[[#This Row],[Column1]]=1,Table2[[#This Row],[Thursday]],Table2[[#This Row],[Friday]])) -> OFF | G10: =IFERROR(_xlfn.LET(_xlpm.s,SUBSTITUTE(IF(Table2[[#This Row],[Column1]]=1,Table2[[#This Row],[Friday]],Table2[[#This Row],[Saturday]])," ",""),IF(_xlpm.s="OFF","OFF",TEXT(MOD(TIMEVALUE(_xlfn.TEXTBEFORE(_xlpm.s,"-"))+0.5,1),"hh:mm")&" - "&TEXT(MOD(TIMEVALUE(_xlfn.TEXTAFTER(_xlpm.s,"-"))+0.5,1),"hh:mm"))),IF(Table2[[#This Row],[Column1]]=1,Table2[[#This Row],[Friday]],Table2[[#This Row],[Saturday]])) -> OFF | H10: =IFERROR(_xlfn.LET(_xlpm.s,SUBSTITUTE(IF(Table2[[#This Row],[Column1]]=1,Table2[[#This Row],[Saturday]],Table2[[#This Row],[Sunday]])," ",""),IF(_xlpm.s="OFF","OFF",TEXT(MOD(TIMEVALUE(_xlfn.TEXTBEFORE(_xlpm.s,"-"))+0.5,1),"hh:mm")&" - "&TEXT(MOD(TIMEVALUE(_xlfn.TEXTAFTER(_xlpm.s,"-"))+0.5,1),"hh:mm"))),IF(Table2[[#This Row],[Column1]]=1,Table2[[#This Row],[Saturday]],Table2[[#This Row],[Sunday]])) -> OFF | I10: =_xlfn.TEXTJOIN(" - ",TRUE, IF(B10="OFF","Mon",""), IF(C10="OFF","Tue",""), IF(D10="OFF","Wed",""), IF(E10="OFF","Thu",""), IF(F10="OFF","Fri",""), IF(G10="OFF","Sat",""), IF(H10="OFF","Sun","")) -> Fri - Sat - Sun | J10: =MOD(Table2[[#This Row],[Break 1]]+TIME(12,0,0),1) -> 0.88541667 | K10: =MOD(Table2[[#This Row],[Break 2]]+TIME(12,0,0),1) -> 0.10416667 | L10: =MOD(Table2[[#This Row],[Lunch]]+TIME(12,0,0),1) -> 0.97916667 | M10: =MOD(Table2[[#This Row],[Break 3]]+TIME(12,0,0),1) -> 0.19791667 | N10: =Table2[[#This Row],[Supervisor]] -> Remmo Panaligan | O10: =TEXT(TIMEVALUE(LEFT(Table2[[#This Row],[EST SHIFT]],5))+12/24,"hh:mm") & " - " & TEXT(TIMEVALUE(RIGHT(Table2[[#This Row],[EST SHIFT]],5))+12/24,"hh:mm") -> 19:00 - 06:00 | P10: =IF(TIMEVALUE(LEFT(O10,FIND("-",O10)-1))>=12/24,0,1) -> 0
A11: =Table2[[#This Row],[Name]] -> Joemie Ann Benedicto | B11: =IFERROR(_xlfn.LET(_xlpm.s,SUBSTITUTE(IF(Table2[[#This Row],[Column1]]=1,Table2[[#This Row],[Sunday]],Table2[[#This Row],[Monday]])," ",""),IF(_xlpm.s="OFF","OFF",TEXT(MOD(TIMEVALUE(_xlfn.TEXTBEFORE(_xlpm.s,"-"))+0.5,1),"hh:mm")&" - "&TEXT(MOD(TIMEVALUE(_xlfn.TEXTAFTER(_xlpm.s,"-"))+0.5,1),"hh:mm"))),IF(Table2[[#This Row],[Column1]]=1,Table2[[#This Row],[Sunday]],Table2[[#This Row],[Monday]])) -> 19:00 - 06:00 | C11: =IFERROR(_xlfn.LET(_xlpm.s,SUBSTITUTE(IF(Table2[[#This Row],[Column1]]=1,Table2[[#This Row],[Monday]],Table2[[#This Row],[Tuesday]])," ",""),IF(_xlpm.s="OFF","OFF",TEXT(MOD(TIMEVALUE(_xlfn.TEXTBEFORE(_xlpm.s,"-"))+0.5,1),"hh:mm")&" - "&TEXT(MOD(TIMEVALUE(_xlfn.TEXTAFTER(_xlpm.s,"-"))+0.5,1),"hh:mm"))),IF(Table2[[#This Row],[Column1]]=1,Table2[[#This Row],[Monday]],Table2[[#This Row],[Tuesday]])) -> 19:00 - 06:00 | D11: =IFERROR(_xlfn.LET(_xlpm.s,SUBSTITUTE(IF(Table2[[#This Row],[Column1]]=1,Table2[[#This Row],[Tuesday]],Table2[[#This Row],[Wednesday]])," ",""),IF(_xlpm.s="OFF","OFF",TEXT(MOD(TIMEVALUE(_xlfn.TEXTBEFORE(_xlpm.s,"-"))+0.5,1),"hh:mm")&" - "&TEXT(MOD(TIMEVALUE(_xlfn.TEXTAFTER(_xlpm.s,"-"))+0.5,1),"hh:mm"))),IF(Table2[[#This Row],[Column1]]=1,Table2[[#This Row],[Tuesday]],Table2[[#This Row],[Wednesday]])) -> 19:00 - 06:00 | E11: =IFERROR(_xlfn.LET(_xlpm.s,SUBSTITUTE(IF(Table2[[#This Row],[Column1]]=1,Table2[[#This Row],[Wednesday]],Table2[[#This Row],[Thursday]])," ",""),IF(_xlpm.s="OFF","OFF",TEXT(MOD(TIMEVALUE(_xlfn.TEXTBEFORE(_xlpm.s,"-"))+0.5,1),"hh:mm")&" - "&TEXT(MOD(TIMEVALUE(_xlfn.TEXTAFTER(_xlpm.s,"-"))+0.5,1),"hh:mm"))),IF(Table2[[#This Row],[Column1]]=1,Table2[[#This Row],[Wednesday]],Table2[[#This Row],[Thursday]])) -> 19:00 - 06:00 | F11: =IFERROR(_xlfn.LET(_xlpm.s,SUBSTITUTE(IF(Table2[[#This Row],[Column1]]=1,Table2[[#This Row],[Thursday]],Table2[[#This Row],[Friday]])," ",""),IF(_xlpm.s="OFF","OFF",TEXT(MOD(TIMEVALUE(_xlfn.TEXTBEFORE(_xlpm.s,"-"))+0.5,1),"hh:mm")&" - "&TEXT(MOD(TIMEVALUE(_xlfn.TEXTAFTER(_xlpm.s,"-"))+0.5,1),"hh:mm"))),IF(Table2[[#This Row],[Column1]]=1,Table2[[#This Row],[Thursday]],Table2[[#This Row],[Friday]])) -> OFF | G11: =IFERROR(_xlfn.LET(_xlpm.s,SUBSTITUTE(IF(Table2[[#This Row],[Column1]]=1,Table2[[#This Row],[Friday]],Table2[[#This Row],[Saturday]])," ",""),IF(_xlpm.s="OFF","OFF",TEXT(MOD(TIMEVALUE(_xlfn.TEXTBEFORE(_xlpm.s,"-"))+0.5,1),"hh:mm")&" - "&TEXT(MOD(TIMEVALUE(_xlfn.TEXTAFTER(_xlpm.s,"-"))+0.5,1),"hh:mm"))),IF(Table2[[#This Row],[Column1]]=1,Table2[[#This Row],[Friday]],Table2[[#This Row],[Saturday]])) -> OFF | H11: =IFERROR(_xlfn.LET(_xlpm.s,SUBSTITUTE(IF(Table2[[#This Row],[Column1]]=1,Table2[[#This Row],[Saturday]],Table2[[#This Row],[Sunday]])," ",""),IF(_xlpm.s="OFF","OFF",TEXT(MOD(TIMEVALUE(_xlfn.TEXTBEFORE(_xlpm.s,"-"))+0.5,1),"hh:mm")&" - "&TEXT(MOD(TIMEVALUE(_xlfn.TEXTAFTER(_xlpm.s,"-"))+0.5,1),"hh:mm"))),IF(Table2[[#This Row],[Column1]]=1,Table2[[#This Row],[Saturday]],Table2[[#This Row],[Sunday]])) -> OFF | I11: =_xlfn.TEXTJOIN(" - ",TRUE, IF(B11="OFF","Mon",""), IF(C11="OFF","Tue",""), IF(D11="OFF","Wed",""), IF(E11="OFF","Thu",""), IF(F11="OFF","Fri",""), IF(G11="OFF","Sat",""), IF(H11="OFF","Sun","")) -> Fri - Sat - Sun | J11: =MOD(Table2[[#This Row],[Break 1]]+TIME(12,0,0),1) -> 0.875 | K11: =MOD(Table2[[#This Row],[Break 2]]+TIME(12,0,0),1) -> 0.09375 | L11: =MOD(Table2[[#This Row],[Lunch]]+TIME(12,0,0),1) -> 0.96875 | M11: =MOD(Table2[[#This Row],[Break 3]]+TIME(12,0,0),1) -> 0.1875 | N11: =Table2[[#This Row],[Supervisor]] -> Remmo Panaligan | O11: =TEXT(TIMEVALUE(LEFT(Table2[[#This Row],[EST SHIFT]],5))+12/24,"hh:mm") & " - " & TEXT(TIMEVALUE(RIGHT(Table2[[#This Row],[EST SHIFT]],5))+12/24,"hh:mm") -> 19:00 - 06:00 | P11: =IF(TIMEVALUE(LEFT(O11,FIND("-",O11)-1))>=12/24,0,1) -> 0
A12: =Table2[[#This Row],[Name]] -> Roy Sagales | B12: =IFERROR(_xlfn.LET(_xlpm.s,SUBSTITUTE(IF(Table2[[#This Row],[Column1]]=1,Table2[[#This Row],[Sunday]],Table2[[#This Row],[Monday]])," ",""),IF(_xlpm.s="OFF","OFF",TEXT(MOD(TIMEVALUE(_xlfn.TEXTBEFORE(_xlpm.s,"-"))+0.5,1),"hh:mm")&" - "&TEXT(MOD(TIMEVALUE(_xlfn.TEXTAFTER(_xlpm.s,"-"))+0.5,1),"hh:mm"))),IF(Table2[[#This Row],[Column1]]=1,Table2[[#This Row],[Sunday]],Table2[[#This Row],[Monday]])) -> 20:00 - 07:00 | C12: =IFERROR(_xlfn.LET(_xlpm.s,SUBSTITUTE(IF(Table2[[#This Row],[Column1]]=1,Table2[[#This Row],[Monday]],Table2[[#This Row],[Tuesday]])," ",""),IF(_xlpm.s="OFF","OFF",TEXT(MOD(TIMEVALUE(_xlfn.TEXTBEFORE(_xlpm.s,"-"))+0.5,1),"hh:mm")&" - "&TEXT(MOD(TIMEVALUE(_xlfn.TEXTAFTER(_xlpm.s,"-"))+0.5,1),"hh:mm"))),IF(Table2[[#This Row],[Column1]]=1,Table2[[#This Row],[Monday]],Table2[[#This Row],[Tuesday]])) -> 20:00 - 07:00 | D12: =IFERROR(_xlfn.LET(_xlpm.s,SUBSTITUTE(IF(Table2[[#This Row],[Column1]]=1,Table2[[#This Row],[Tuesday]],Table2[[#This Row],[Wednesday]])," ",""),IF(_xlpm.s="OFF","OFF",TEXT(MOD(TIMEVALUE(_xlfn.TEXTBEFORE(_xlpm.s,"-"))+0.5,1),"hh:mm")&" - "&TEXT(MOD(TIMEVALUE(_xlfn.TEXTAFTER(_xlpm.s,"-"))+0.5,1),"hh:mm"))),IF(Table2[[#This Row],[Column1]]=1,Table2[[#This Row],[Tuesday]],Table2[[#This Row],[Wednesday]])) -> OFF | E12: =IFERROR(_xlfn.LET(_xlpm.s,SUBSTITUTE(IF(Table2[[#This Row],[Column1]]=1,Table2[[#This Row],[Wednesday]],Table2[[#This Row],[Thursday]])," ",""),IF(_xlpm.s="OFF","OFF",TEXT(MOD(TIMEVALUE(_xlfn.TEXTBEFORE(_xlpm.s,"-"))+0.5,1),"hh:mm")&" - "&TEXT(MOD(TIMEVALUE(_xlfn.TEXTAFTER(_xlpm.s,"-"))+0.5,1),"hh:mm"))),IF(Table2[[#This Row],[Column1]]=1,Table2[[#This Row],[Wednesday]],Table2[[#This Row],[Thursday]])) -> OFF | F12: =IFERROR(_xlfn.LET(_xlpm.s,SUBSTITUTE(IF(Table2[[#This Row],[Column1]]=1,Table2[[#This Row],[Thursday]],Table2[[#This Row],[Friday]])," ",""),IF(_xlpm.s="OFF","OFF",TEXT(MOD(TIMEVALUE(_xlfn.TEXTBEFORE(_xlpm.s,"-"))+0.5,1),"hh:mm")&" - "&TEXT(MOD(TIMEVALUE(_xlfn.TEXTAFTER(_xlpm.s,"-"))+0.5,1),"hh:mm"))),IF(Table2[[#This Row],[Column1]]=1,Table2[[#This Row],[Thursday]],Table2[[#This Row],[Friday]])) -> OFF | G12: =IFERROR(_xlfn.LET(_xlpm.s,SUBSTITUTE(IF(Table2[[#This Row],[Column1]]=1,Table2[[#This Row],[Friday]],Table2[[#This Row],[Saturday]])," ",""),IF(_xlpm.s="OFF","OFF",TEXT(MOD(TIMEVALUE(_xlfn.TEXTBEFORE(_xlpm.s,"-"))+0.5,1),"hh:mm")&" - "&TEXT(MOD(TIMEVALUE(_xlfn.TEXTAFTER(_xlpm.s,"-"))+0.5,1),"hh:mm"))),IF(Table2[[#This Row],[Column1]]=1,Table2[[#This Row],[Friday]],Table2[[#This Row],[Saturday]])) -> 20:00 - 07:00 | H12: =IFERROR(_xlfn.LET(_xlpm.s,SUBSTITUTE(IF(Table2[[#This Row],[Column1]]=1,Table2[[#This Row],[Saturday]],Table2[[#This Row],[Sunday]])," ",""),IF(_xlpm.s="OFF","OFF",TEXT(MOD(TIMEVALUE(_xlfn.TEXTBEFORE(_xlpm.s,"-"))+0.5,1),"hh:mm")&" - "&TEXT(MOD(TIMEVALUE(_xlfn.TEXTAFTER(_xlpm.s,"-"))+0.5,1),"hh:mm"))),IF(Table2[[#This Row],[Column1]]=1,Table2[[#This Row],[Saturday]],Table2[[#This Row],[Sunday]])) -> 20:00 - 07:00 | I12: =_xlfn.TEXTJOIN(" - ",TRUE, IF(B12="OFF","Mon",""), IF(C12="OFF","Tue",""), IF(D12="OFF","Wed",""), IF(E12="OFF","Thu",""), IF(F12="OFF","Fri",""), IF(G12="OFF","Sat",""), IF(H12="OFF","Sun","")) -> Wed - Thu - Fri | J12: =MOD(Table2[[#This Row],[Break 1]]+TIME(12,0,0),1) -> 0.90625 | K12: =MOD(Table2[[#This Row],[Break 2]]+TIME(12,0,0),1) -> 0.11458333 | L12: =MOD(Table2[[#This Row],[Lunch]]+TIME(12,0,0),1) -> 0.98958333 | M12: =MOD(Table2[[#This Row],[Break 3]]+TIME(12,0,0),1) -> 0.21875 | N12: =Table2[[#This Row],[Supervisor]] -> Michael Dominguez | O12: =TEXT(TIMEVALUE(LEFT(Table2[[#This Row],[EST SHIFT]],5))+12/24,"hh:mm") & " - " & TEXT(TIMEVALUE(RIGHT(Table2[[#This Row],[EST SHIFT]],5))+12/24,"hh:mm") -> 20:00 - 07:00 | P12: =IF(TIMEVALUE(LEFT(O12,FIND("-",O12)-1))>=12/24,0,1) -> 0
A13: =Table2[[#This Row],[Name]] -> Shiela Mae Laroa | B13: =IFERROR(_xlfn.LET(_xlpm.s,SUBSTITUTE(IF(Table2[[#This Row],[Column1]]=1,Table2[[#This Row],[Sunday]],Table2[[#This Row],[Monday]])," ",""),IF(_xlpm.s="OFF","OFF",TEXT(MOD(TIMEVALUE(_xlfn.TEXTBEFORE(_xlpm.s,"-"))+0.5,1),"hh:mm")&" - "&TEXT(MOD(TIMEVALUE(_xlfn.TEXTAFTER(_xlpm.s,"-"))+0.5,1),"hh:mm"))),IF(Table2[[#This Row],[Column1]]=1,Table2[[#This Row],[Sunday]],Table2[[#This Row],[Monday]])) -> 20:00 - 07:00 | C13: =IFERROR(_xlfn.LET(_xlpm.s,SUBSTITUTE(IF(Table2[[#This Row],[Column1]]=1,Table2[[#This Row],[Monday]],Table2[[#This Row],[Tuesday]])," ",""),IF(_xlpm.s="OFF","OFF",TEXT(MOD(TIMEVALUE(_xlfn.TEXTBEFORE(_xlpm.s,"-"))+0.5,1),"hh:mm")&" - "&TEXT(MOD(TIMEVALUE(_xlfn.TEXTAFTER(_xlpm.s,"-"))+0.5,1),"hh:mm"))),IF(Table2[[#This Row],[Column1]]=1,Table2[[#This Row],[Monday]],Table2[[#This Row],[Tuesday]])) -> 20:00 - 07:00 | D13: =IFERROR(_xlfn.LET(_xlpm.s,SUBSTITUTE(IF(Table2[[#This Row],[Column1]]=1,Table2[[#This Row],[Tuesday]],Table2[[#This Row],[Wednesday]])," ",""),IF(_xlpm.s="OFF","OFF",TEXT(MOD(TIMEVALUE(_xlfn.TEXTBEFORE(_xlpm.s,"-"))+0.5,1),"hh:mm")&" - "&TEXT(MOD(TIMEVALUE(_xlfn.TEXTAFTER(_xlpm.s,"-"))+0.5,1),"hh:mm"))),IF(Table2[[#This Row],[Column1]]=1,Table2[[#This Row],[Tuesday]],Table2[[#This Row],[Wednesday]])) -> 20:00 - 07:00 | E13: =IFERROR(_xlfn.LET(_xlpm.s,SUBSTITUTE(IF(Table2[[#This Row],[Column1]]=1,Table2[[#This Row],[Wednesday]],Table2[[#This Row],[Thursday]])," ",""),IF(_xlpm.s="OFF","OFF",TEXT(MOD(TIMEVALUE(_xlfn.TEXTBEFORE(_xlpm.s,"-"))+0.5,1),"hh:mm")&" - "&TEXT(MOD(TIMEVALUE(_xlfn.TEXTAFTER(_xlpm.s,"-"))+0.5,1),"hh:mm"))),IF(Table2[[#This Row],[Column1]]=1,Table2[[#This Row],[Wednesday]],Table2[[#This Row],[Thursday]])) -> 20:00 - 07:00 | F13: =IFERROR(_xlfn.LET(_xlpm.s,SUBSTITUTE(IF(Table2[[#This Row],[Column1]]=1,Table2[[#This Row],[Thursday]],Table2[[#This Row],[Friday]])," ",""),IF(_xlpm.s="OFF","OFF",TEXT(MOD(TIMEVALUE(_xlfn.TEXTBEFORE(_xlpm.s,"-"))+0.5,1),"hh:mm")&" - "&TEXT(MOD(TIMEVALUE(_xlfn.TEXTAFTER(_xlpm.s,"-"))+0.5,1),"hh:mm"))),IF(Table2[[#This Row],[Column1]]=1,Table2[[#This Row],[Thursday]],Table2[[#This Row],[Friday]])) -> OFF | G13: =IFERROR(_xlfn.LET(_xlpm.s,SUBSTITUTE(IF(Table2[[#This Row],[Column1]]=1,Table2[[#This Row],[Friday]],Table2[[#This Row],[Saturday]])," ",""),IF(_xlpm.s="OFF","OFF",TEXT(MOD(TIMEVALUE(_xlfn.TEXTBEFORE(_xlpm.s,"-"))+0.5,1),"hh:mm")&" - "&TEXT(MOD(TIMEVALUE(_xlfn.TEXTAFTER(_xlpm.s,"-"))+0.5,1),"hh:mm"))),IF(Table2[[#This Row],[Column1]]=1,Table2[[#This Row],[Friday]],Table2[[#This Row],[Saturday]])) -> OFF | H13: =IFERROR(_xlfn.LET(_xlpm.s,SUBSTITUTE(IF(Table2[[#This Row],[Column1]]=1,Table2[[#This Row],[Saturday]],Table2[[#This Row],[Sunday]])," ",""),IF(_xlpm.s="OFF","OFF",TEXT(MOD(TIMEVALUE(_xlfn.TEXTBEFORE(_xlpm.s,"-"))+0.5,1),"hh:mm")&" - "&TEXT(MOD(TIMEVALUE(_xlfn.TEXTAFTER(_xlpm.s,"-"))+0.5,1),"hh:mm"))),IF(Table2[[#This Row],[Column1]]=1,Table2[[#This Row],[Saturday]],Table2[[#This Row],[Sunday]])) -> OFF | I13: =_xlfn.TEXTJOIN(" - ",TRUE, IF(B13="OFF","Mon",""), IF(C13="OFF","Tue",""), IF(D13="OFF","Wed",""), IF(E13="OFF","Thu",""), IF(F13="OFF","Fri",""), IF(G13="OFF","Sat",""), IF(H13="OFF","Sun","")) -> Fri - Sat - Sun | J13: =MOD(Table2[[#This Row],[Break 1]]+TIME(12,0,0),1) -> 0.91666667 | K13: =MOD(Table2[[#This Row],[Break 2]]+TIME(12,0,0),1) -> 0.020833333 | L13: =MOD(Table2[[#This Row],[Lunch]]+TIME(12,0,0),1) -> 0.125 | M13: =MOD(Table2[[#This Row],[Break 3]]+TIME(12,0,0),1) -> 0.21875 | N13: =Table2[[#This Row],[Supervisor]] -> Manilyn Abellar | O13: =TEXT(TIMEVALUE(LEFT(Table2[[#This Row],[EST SHIFT]],5))+12/24,"hh:mm") & " - " & TEXT(TIMEVALUE(RIGHT(Table2[[#This Row],[EST SHIFT]],5))+12/24,"hh:mm") -> 20:00 - 07:00 | P13: =IF(TIMEVALUE(LEFT(O13,FIND("-",O13)-1))>=12/24,0,1) -> 0
... A67: =Table2[[#This Row],[Name]] -> Mary Angelie Fajardo | B67: =IFERROR(_xlfn.LET(_xlpm.s,SUBSTITUTE(IF(Table2[[#This Row],[Column1]]=1,Table2[[#This Row],[Sunday]],Table2[[#This Row],[Monday]])," ",""),IF(_xlpm.s="OFF","OFF",TEXT(MOD(TIMEVALUE(_xlfn.TEXTBEFORE(_xlpm.s,"-"))+0.5,1),"hh:mm")&" - "&TEXT(MOD(TIMEVALUE(_xlfn.TEXTAFTER(_xlpm.s,"-"))+0.5,1),"hh:mm"))),IF(Table2[[#This Row],[Column1]]=1,Table2[[#This Row],[Sunday]],Table2[[#This Row],[Monday]])) -> 09:00 - 20:00 | C67: =IFERROR(_xlfn.LET(_xlpm.s,SUBSTITUTE(IF(Table2[[#This Row],[Column1]]=1,Table2[[#This Row],[Monday]],Table2[[#This Row],[Tuesday]])," ",""),IF(_xlpm.s="OFF","OFF",TEXT(MOD(TIMEVALUE(_xlfn.TEXTBEFORE(_xlpm.s,"-"))+0.5,1),"hh:mm")&" - "&TEXT(MOD(TIMEVALUE(_xlfn.TEXTAFTER(_xlpm.s,"-"))+0.5,1),"hh:mm"))),IF(Table2[[#This Row],[Column1]]=1,Table2[[#This Row],[Monday]],Table2[[#This Row],[Tuesday]])) -> OFF | D67: =IFERROR(_xlfn.LET(_xlpm.s,SUBSTITUTE(IF(Table2[[#This Row],[Column1]]=1,Table2[[#This Row],[Tuesday]],Table2[[#This Row],[Wednesday]])," ",""),IF(_xlpm.s="OFF","OFF",TEXT(MOD(TIMEVALUE(_xlfn.TEXTBEFORE(_xlpm.s,"-"))+0.5,1),"hh:mm")&" - "&TEXT(MOD(TIMEVALUE(_xlfn.TEXTAFTER(_xlpm.s,"-"))+0.5,1),"hh:mm"))),IF(Table2[[#This Row],[Column1]]=1,Table2[[#This Row],[Tuesday]],Table2[[#This Row],[Wednesday]])) -> OFF | E67: =IFERROR(_xlfn.LET(_xlpm.s,SUBSTITUTE(IF(Table2[[#This Row],[Column1]]=1,Table2[[#This Row],[Wednesday]],Table2[[#This Row],[Thursday]])," ",""),IF(_xlpm.s="OFF","OFF",TEXT(MOD(TIMEVALUE(_xlfn.TEXTBEFORE(_xlpm.s,"-"))+0.5,1),"hh:mm")&" - "&TEXT(MOD(TIMEVALUE(_xlfn.TEXTAFTER(_xlpm.s,"-"))+0.5,1),"hh:mm"))),IF(Table2[[#This Row],[Column1]]=1,Table2[[#This Row],[Wednesday]],Table2[[#This Row],[Thursday]])) -> OFF | F67: =IFERROR(_xlfn.LET(_xlpm.s,SUBSTITUTE(IF(Table2[[#This Row],[Column1]]=1,Table2[[#This Row],[Thursday]],Table2[[#This Row],[Friday]])," ",""),IF(_xlpm.s="OFF","OFF",TEXT(MOD(TIMEVALUE(_xlfn.TEXTBEFORE(_xlpm.s,"-"))+0.5,1),"hh:mm")&" - "&TEXT(MOD(TIMEVALUE(_xlfn.TEXTAFTER(_xlpm.s,"-"))+0.5,1),"hh:mm"))),IF(Table2[[#This Row],[Column1]]=1,Table2[[#This Row],[Thursday]],Table2[[#This Row],[Friday]])) -> 09:00 - 20:00 | G67: =IFERROR(_xlfn.LET(_xlpm.s,SUBSTITUTE(IF(Table2[[#This Row],[Column1]]=1,Table2[[#This Row],[Friday]],Table2[[#This Row],[Saturday]])," ",""),IF(_xlpm.s="OFF","OFF",TEXT(MOD(TIMEVALUE(_xlfn.TEXTBEFORE(_xlpm.s,"-"))+0.5,1),"hh:mm")&" - "&TEXT(MOD(TIMEVALUE(_xlfn.TEXTAFTER(_xlpm.s,"-"))+0.5,1),"hh:mm"))),IF(Table2[[#This Row],[Column1]]=1,Table2[[#This Row],[Friday]],Table2[[#This Row],[Saturday]])) -> 09:00 - 20:00 | H67: =IFERROR(_xlfn.LET(_xlpm.s,SUBSTITUTE(IF(Table2[[#This Row],[Column1]]=1,Table2[[#This Row],[Saturday]],Table2[[#This Row],[Sunday]])," ",""),IF(_xlpm.s="OFF","OFF",TEXT(MOD(TIMEVALUE(_xlfn.TEXTBEFORE(_xlpm.s,"-"))+0.5,1),"hh:mm")&" - "&TEXT(MOD(TIMEVALUE(_xlfn.TEXTAFTER(_xlpm.s,"-"))+0.5,1),"hh:mm"))),IF(Table2[[#This Row],[Column1]]=1,Table2[[#This Row],[Saturday]],Table2[[#This Row],[Sunday]])) -> 09:00 - 20:00 | I67: =_xlfn.TEXTJOIN(" - ",TRUE, IF(B67="OFF","Mon",""), IF(C67="OFF","Tue",""), IF(D67="OFF","Wed",""), IF(E67="OFF","Thu",""), IF(F67="OFF","Fri",""), IF(G67="OFF","Sat",""), IF(H67="OFF","Sun","")) -> Tue - Wed - Thu | J67: =MOD(Table2[[#This Row],[Break 1]]+TIME(12,0,0),1) -> 0.45833333 | K67: =MOD(Table2[[#This Row],[Break 2]]+TIME(12,0,0),1) -> 0.5625 | L67: =MOD(Table2[[#This Row],[Lunch]]+TIME(12,0,0),1) -> 0.64583333 | M67: =MOD(Table2[[#This Row],[Break 3]]+TIME(12,0,0),1) -> 0.79166667 | N67: =Table2[[#This Row],[Supervisor]] -> Christopher Rodas | O67: =TEXT(TIMEVALUE(LEFT(Table2[[#This Row],[EST SHIFT]],5))+12/24,"hh:mm") & " - " & TEXT(TIMEVALUE(RIGHT(Table2[[#This Row],[EST SHIFT]],5))+12/24,"hh:mm") -> 09:00 - 20:00 | P67: =IF(TIMEVALUE(LEFT(O67,FIND("-",O67)-1))>=12/24,0,1) -> 1

Sheet EST_OLD
A1: Name | B1: Monday | C1: Tuesday | D1: Wednesday | E1: Thursday | F1: Friday | G1: Saturday | H1: Sunday | I1: Rest Day | J1: Break 1 | K1: Break 2 | L1: Lunch | M1: Break 3 | N1: Supervisor | O1: Shift EST | P1: Column1
A2: Aireen Balanon | N2: Remmo Panaligan | P2: =IF(O2="OFF",0, IF(VALUE(LEFT(O2,2))<12,0,1)) -> #VALUE!
A3: Alec Christian Palabay | N3: Remmo Panaligan | P3: =IF(O3="OFF",0, IF(VALUE(LEFT(O3,2))<12,0,1)) -> #VALUE!
A4: Andrei Mark Llenos | N4: Charmane Briones | P4: =IF(O4="OFF",0, IF(VALUE(LEFT(O4,2))<12,0,1)) -> #VALUE!
A5: Antonio Agda | N5: Charmane Briones | P5: =IF(O5="OFF",0, IF(VALUE(LEFT(O5,2))<12,0,1)) -> #VALUE!
A6: Ash Belarmino | N6: Christopher Rodas | P6: =IF(O6="OFF",0, IF(VALUE(LEFT(O6,2))<12,0,1)) -> #VALUE!
A7: Aysha Sagira Macalandong | N7: Michael Dominguez | P7: =IF(O7="OFF",0, IF(VALUE(LEFT(O7,2))<12,0,1)) -> #VALUE!
A8: Azilean Khrista Almazan | N8: Anmecha Valencia | P8: =IF(O8="OFF",0, IF(VALUE(LEFT(O8,2))<12,0,1)) -> #VALUE!
A9: Benedict Ermitano | N9: Michael Dominguez | P9: =IF(O9="OFF",0, IF(VALUE(LEFT(O9,2))<12,0,1)) -> #VALUE!
A10: Carlos Kiamco | N10: Christopher Rodas | P10: =IF(O10="OFF",0, IF(VALUE(LEFT(O10,2))<12,0,1)) -> #VALUE!
A11: Cesthel Narciso | N11: Charmane Briones | P11: =IF(O11="OFF",0, IF(VALUE(LEFT(O11,2))<12,0,1)) -> #VALUE!
A12: Charisse Capuno | N12: Anmecha Valencia | P12: =IF(O12="OFF",0, IF(VALUE(LEFT(O12,2))<12,0,1)) -> #VALUE!
A13: Chris Paul Dalut | N13: Anmecha Valencia | P13: =IF(O13="OFF",0, IF(VALUE(LEFT(O13,2))<12,0,1)) -> #VALUE!
... A68: William Nava | N68: Anmecha Valencia | P68: =IF(O68="OFF",0, IF(VALUE(LEFT(O68,2))<12,0,1)) -> #VALUE!

Sheet PH_OLD
A1: Name | B1: Monday | C1: Tuesday | D1: Wednesday | E1: Thursday | F1: Friday | G1: Saturday | H1: Sunday | I1: Rest Day | J1: Break 1 | K1: Break 2 | L1: Lunch | M1: Break 3 | N1: Supervisor | O1: Shift | P1: Column1
A2: =EST_OLD!A2 -> Aireen Balanon | N2: =EST_OLD!N2 -> Remmo Panaligan
A3: =EST_OLD!A3 -> Alec Christian Palabay | N3: =EST_OLD!N3 -> Remmo Panaligan
A4: =EST_OLD!A4 -> Andrei Mark Llenos | N4: =EST_OLD!N4 -> Charmane Briones
A5: =EST_OLD!A5 -> Antonio Agda | N5: =EST_OLD!N5 -> Charmane Briones
A6: =EST_OLD!A6 -> Ash Belarmino | N6: =EST_OLD!N6 -> Christopher Rodas
A7: =EST_OLD!A7 -> Aysha Sagira Macalandong | N7: =EST_OLD!N7 -> Michael Dominguez
A8: =EST_OLD!A8 -> Azilean Khrista Almazan | N8: =EST_OLD!N8 -> Anmecha Valencia
A9: =EST_OLD!A9 -> Benedict Ermitano | N9: =EST_OLD!N9 -> Michael Dominguez
A10: =EST_OLD!A10 -> Carlos Kiamco | N10: =EST_OLD!N10 -> Christopher Rodas
A11: =EST_OLD!A11 -> Cesthel Narciso | N11: =EST_OLD!N11 -> Charmane Briones
